Workbook
Name 勤務時間: #REF!
Name 現場名曜日: #REF!
Name ランク: '金額'!$A$32:$A$38
Name 時間数: '金額'!$H$3:$H$28
Name 水: #REF!
Name 祝日リスト: #REF!
Name 出勤退勤時間: #REF!
Name 祝前日: #REF!
Name 月: #REF!
Name 店舗名: #REF!
Name 現場名: #REF!
Name 日: #REF!
Name 時間数: #REF!
Name 木: #REF!
Name 金: #REF!
Name 曜日: #REF!
Name 曜日: #REF!
Name 登録名: '外注連絡票'!$D$7:$D$93
Name 勤務時間: '金額'!$I$3:$I$28
Name 氏名: '1.入力表'!$F$4
Name 現場名曜日: '金額'!$B$3:$B$28
Name 氏名: '2.入力表'!$G$4
Name 祝前日リスト: #REF!
Name 火: #REF!
Name 土: #REF!
Name 時給表: #REF!
Name 案件名: #REF!
Name リスト全体: '外注連絡票'!$C$7:$P$93
Name ラウンドバー合計日数: #REF!

Sheet 1.入力表
N2: 支払総計 | O2: =$O$7+$P$7 -> 0
C6: 日程 | D6: 曜日 | E6: 現場 | F6: 案件名 | H6: 勤務時間 | I6: 実働 | J6: 詳細 | L6: 時給 | M6: UP給 | N6: 日給 | O6: 案件単価 | P6: 交通費
B7: =IF($K7="","",(VLOOKUP($K7,'判定表'!$B$3:$G$105,6,FALSE))) | C7: 合計 | F7: =SUBTOTAL(3, F8:F1677) -> 0 | I7: =SUBTOTAL(9, I8:I1677) -> 0 | L7: 合計 | M7: =SUBTOTAL(9, M8:M1677) -> 0 | N7: =SUBTOTAL(9, N8:N1677) -> 0 | O7: =SUBTOTAL(9, O8:O1677) -> 0 | P7: =SUBTOTAL(9,P8:P1677) -> 0
B8: =IF($K8="","",(VLOOKUP($K8,'判定表'!$B$3:$G$105,6,FALSE))) | D8: =IF(C8="","",upper(TEXT(C8, "DDD"))) | E8: =IF(F8="","",VLOOKUP($F8,'金額'!$B$3:$K$44,10,FALSE)) | G8: =IF($F8="","",(VLOOKUP($F8,'金額'!$B$3:$E$114,2,FALSE))) | H8: =IF(F8="","",VLOOKUP($F8,'金額'!$B$3:$I$44,8,FALSE)) | I8: =IF(F8="","",VLOOKUP($F8,'金額'!$B$3:$I$44,7,FALSE)) | L8: =IF($I8="","",IF(AND($B8="K",$E8="KTN"),2000,IF(AND($B8="K",$E8="WHZ"),2000,IF($E8="MAHA",1500,IF($G8=0,(VLOOKUP($K8,'判定表'!$B$3:$G$96,2,FALSE)),0))))) | M8: =IF($K8="","",IF($E8="ANC",(VLOOKUP($K8,'判定表'!$B$3:$G$95,3,FALSE)),IF(OR($E8="KTN",$E8="WHZ"),(VLOOKUP($K8,'判定表'!$B$3:$G$95,4,FALSE)*I8),0))) | N8: =IF($I8="","",IF($K8="","",IF($G8=1,(VLOOKUP($F8,'金額'!$B$3:$J$114,3,FALSE)),0))) | O8: =IF(F8="","",(L8*I8+M8+N8)) | P8: =IF($K8="","",IF($E8="KTN",(VLOOKUP($K8,'判定表'!$B$3:$I$95,8,FALSE)),IF($I8="","",(VLOOKUP($F8,'金額'!$B$3:$J$114,9,FALSE)))))
B9: =IF($K9="","",(VLOOKUP($K9,'判定表'!$B$3:$G$105,6,FALSE))) | D9: =IF(C9="","",upper(TEXT(C9, "DDD"))) | E9: =IF(F9="","",VLOOKUP($F9,'金額'!$B$3:$K$44,10,FALSE)) | G9: =IF($F9="","",(VLOOKUP($F9,'金額'!$B$3:$E$114,2,FALSE))) | H9: =IF(F9="","",VLOOKUP($F9,'金額'!$B$3:$I$44,8,FALSE)) | I9: =IF(F9="","",VLOOKUP($F9,'金額'!$B$3:$I$44,7,FALSE)) | L9: =IF($I9="","",IF(AND($B9="K",$E9="KTN"),2000,IF(AND($B9="K",$E9="WHZ"),2000,IF($E9="MAHA",1500,IF($G9=0,(VLOOKUP($K9,'判定表'!$B$3:$G$96,2,FALSE)),0))))) | M9: =IF($K9="","",IF($E9="ANC",(VLOOKUP($K9,'判定表'!$B$3:$G$95,3,FALSE)),IF(OR($E9="KTN",$E9="WHZ"),(VLOOKUP($K9,'判定表'!$B$3:$G$95,4,FALSE)*I9),0))) | N9: =IF($I9="","",IF($K9="","",IF($G9=1,(VLOOKUP($F9,'金額'!$B$3:$J$114,3,FALSE)),0))) | O9: =IF(F9="","",(L9*I9+M9+N9)) | P9: =IF($K9="","",IF($E9="KTN",(VLOOKUP($K9,'判定表'!$B$3:$I$95,8,FALSE)),IF($I9="","",(VLOOKUP($F9,'金額'!$B$3:$J$114,9,FALSE)))))
B10: =IF($K10="","",(VLOOKUP($K10,'判定表'!$B$3:$G$105,6,FALSE))) | D10: =IF(C10="","",upper(TEXT(C10, "DDD"))) | E10: =IF(F10="","",VLOOKUP($F10,'金額'!$B$3:$K$44,10,FALSE)) | G10: =IF($F10="","",(VLOOKUP($F10,'金額'!$B$3:$E$114,2,FALSE))) | H10: =IF(F10="","",VLOOKUP($F10,'金額'!$B$3:$I$44,8,FALSE)) | I10: =IF(F10="","",VLOOKUP($F10,'金額'!$B$3:$I$44,7,FALSE)) | L10: =IF($I10="","",IF(AND($B10="K",$E10="KTN"),2000,IF(AND($B10="K",$E10="WHZ"),2000,IF($E10="MAHA",1500,IF($G10=0,(VLOOKUP($K10,'判定表'!$B$3:$G$96,2,FALSE)),0))))) | M10: =IF($K10="","",IF($E10="ANC",(VLOOKUP($K10,'判定表'!$B$3:$G$95,3,FALSE)),IF(OR($E10="KTN",$E10="WHZ"),(VLOOKUP($K10,'判定表'!$B$3:$G$95,4,FALSE)*I10),0))) | N10: =IF($I10="","",IF($K10="","",IF($G10=1,(VLOOKUP($F10,'金額'!$B$3:$J$114,3,FALSE)),0))) | O10: =IF(F10="","",(L10*I10+M10+N10)) | P10: =IF($K10="","",IF($E10="KTN",(VLOOKUP($K10,'判定表'!$B$3:$I$95,8,FALSE)),IF($I10="","",(VLOOKUP($F10,'金額'!$B$3:$J$114,9,FALSE)))))
B11: =IF($K11="","",(VLOOKUP($K11,'判定表'!$B$3:$G$105,6,FALSE))) | D11: =IF(C11="","",upper(TEXT(C11, "DDD"))) | E11: =IF(F11="","",VLOOKUP($F11,'金額'!$B$3:$K$44,10,FALSE)) | G11: =IF($F11="","",(VLOOKUP($F11,'金額'!$B$3:$E$114,2,FALSE))) | H11: =IF(F11="","",VLOOKUP($F11,'金額'!$B$3:$I$44,8,FALSE)) | I11: =IF(F11="","",VLOOKUP($F11,'金額'!$B$3:$I$44,7,FALSE)) | L11: =IF($I11="","",IF(AND($B11="K",$E11="KTN"),2000,IF(AND($B11="K",$E11="WHZ"),2000,IF($E11="MAHA",1500,IF($G11=0,(VLOOKUP($K11,'判定表'!$B$3:$G$96,2,FALSE)),0))))) | M11: =IF($K11="","",IF($E11="ANC",(VLOOKUP($K11,'判定表'!$B$3:$G$95,3,FALSE)),IF(OR($E11="KTN",$E11="WHZ"),(VLOOKUP($K11,'判定表'!$B$3:$G$95,4,FALSE)*I11),0))) | N11: =IF($I11="","",IF($K11="","",IF($G11=1,(VLOOKUP($F11,'金額'!$B$3:$J$114,3,FALSE)),0))) | O11: =IF(F11="","",(L11*I11+M11+N11)) | P11: =IF($K11="","",IF($E11="KTN",(VLOOKUP($K11,'判定表'!$B$3:$I$95,8,FALSE)),IF($I11="","",(VLOOKUP($F11,'金額'!$B$3:$J$114,9,FALSE)))))
B12: =IF($K12="","",(VLOOKUP($K12,'判定表'!$B$3:$G$105,6,FALSE))) | D12: =IF(C12="","",upper(TEXT(C12, "DDD"))) | E12: =IF(F12="","",VLOOKUP($F12,'金額'!$B$3:$K$44,10,FALSE)) | G12: =IF($F12="","",(VLOOKUP($F12,'金額'!$B$3:$E$114,2,FALSE))) | H12: =IF(F12="","",VLOOKUP($F12,'金額'!$B$3:$I$44,8,FALSE)) | I12: =IF(F12="","",VLOOKUP($F12,'金額'!$B$3:$I$44,7,FALSE)) | L12: =IF($I12="","",IF(AND($B12="K",$E12="KTN"),2000,IF(AND($B12="K",$E12="WHZ"),2000,IF($E12="MAHA",1500,IF($G12=0,(VLOOKUP($K12,'判定表'!$B$3:$G$96,2,FALSE)),0))))) | M12: =IF($K12="","",IF($E12="ANC",(VLOOKUP($K12,'判定表'!$B$3:$G$95,3,FALSE)),IF(OR($E12="KTN",$E12="WHZ"),(VLOOKUP($K12,'判定表'!$B$3:$G$95,4,FALSE)*I12),0))) | N12: =IF($I12="","",IF($K12="","",IF($G12=1,(VLOOKUP($F12,'金額'!$B$3:$J$114,3,FALSE)),0))) | O12: =IF(F12="","",(L12*I12+M12+N12)) | P12: =IF($K12="","",IF($E12="KTN",(VLOOKUP($K12,'判定表'!$B$3:$I$95,8,FALSE)),IF($I12="","",(VLOOKUP($F12,'金額'!$B$3:$J$114,9,FALSE)))))
B13: =IF($K13="","",(VLOOKUP($K13,'判定表'!$B$3:$G$105,6,FALSE))) | D13: =IF(C13="","",upper(TEXT(C13, "DDD"))) | E13: =IF(F13="","",VLOOKUP($F13,'金額'!$B$3:$K$44,10,FALSE)) | G13: =IF($F13="","",(VLOOKUP($F13,'金額'!$B$3:$E$114,2,FALSE))) | H13: =IF(F13="","",VLOOKUP($F13,'金額'!$B$3:$I$44,8,FALSE)) | I13: =IF(F13="","",VLOOKUP($F13,'金額'!$B$3:$I$44,7,FALSE)) | L13: =IF($I13="","",IF(AND($B13="K",$E13="KTN"),2000,IF(AND($B13="K",$E13="WHZ"),2000,IF($E13="MAHA",1500,IF($G13=0,(VLOOKUP($K13,'判定表'!$B$3:$G$96,2,FALSE)),0))))) | M13: =IF($K13="","",IF($E13="ANC",(VLOOKUP($K13,'判定表'!$B$3:$G$95,3,FALSE)),IF(OR($E13="KTN",$E13="WHZ"),(VLOOKUP($K13,'判定表'!$B$3:$G$95,4,FALSE)*I13),0))) | N13: =IF($I13="","",IF($K13="","",IF($G13=1,(VLOOKUP($F13,'金額'!$B$3:$J$114,3,FALSE)),0))) | O13: =IF(F13="","",(L13*I13+M13+N13)) | P13: =IF($K13="","",IF($E13="KTN",(VLOOKUP($K13,'判定表'!$B$3:$I$95,8,FALSE)),IF($I13="","",(VLOOKUP($F13,'金額'!$B$3:$J$114,9,FALSE)))))
B14: =IF($K14="","",(VLOOKUP($K14,'判定表'!$B$3:$G$105,6,FALSE))) | D14: =IF(C14="","",upper(TEXT(C14, "DDD"))) | E14: =IF(F14="","",VLOOKUP($F14,'金額'!$B$3:$K$44,10,FALSE)) | G14: =IF($F14="","",(VLOOKUP($F14,'金額'!$B$3:$E$114,2,FALSE))) | H14: =IF(F14="","",VLOOKUP($F14,'金額'!$B$3:$I$44,8,FALSE)) | I14: =IF(F14="","",VLOOKUP($F14,'金額'!$B$3:$I$44,7,FALSE)) | L14: =IF($I14="","",IF(AND($B14="K",$E14="KTN"),2000,IF(AND($B14="K",$E14="WHZ"),2000,IF($E14="MAHA",1500,IF($G14=0,(VLOOKUP($K14,'判定表'!$B$3:$G$96,2,FALSE)),0))))) | M14: =IF($K14="","",IF($E14="ANC",(VLOOKUP($K14,'判定表'!$B$3:$G$95,3,FALSE)),IF(OR($E14="KTN",$E14="WHZ"),(VLOOKUP($K14,'判定表'!$B$3:$G$95,4,FALSE)*I14),0))) | N14: =IF($I14="","",IF($K14="","",IF($G14=1,(VLOOKUP($F14,'金額'!$B$3:$J$114,3,FALSE)),0))) | O14: =IF(F14="","",(L14*I14+M14+N14)) | P14: =IF($K14="","",IF($E14="KTN",(VLOOKUP($K14,'判定表'!$B$3:$I$95,8,FALSE)),IF($I14="","",(VLOOKUP($F14,'金額'!$B$3:$J$114,9,FALSE)))))
B15: =IF($K15="","",(VLOOKUP($K15,'判定表'!$B$3:$G$105,6,FALSE))) | D15: =IF(C15="","",upper(TEXT(C15, "DDD"))) | E15: =IF(F15="","",VLOOKUP($F15,'金額'!$B$3:$K$44,10,FALSE)) | G15: =IF($F15="","",(VLOOKUP($F15,'金額'!$B$3:$E$114,2,FALSE))) | H15: =IF(F15="","",VLOOKUP($F15,'金額'!$B$3:$I$44,8,FALSE)) | I15: =IF(F15="","",VLOOKUP($F15,'金額'!$B$3:$I$44,7,FALSE)) | L15: =IF($I15="","",IF(AND($B15="K",$E15="KTN"),2000,IF(AND($B15="K",$E15="WHZ"),2000,IF($E15="MAHA",1500,IF($G15=0,(VLOOKUP($K15,'判定表'!$B$3:$G$96,2,FALSE)),0))))) | M15: =IF($K15="","",IF($E15="ANC",(VLOOKUP($K15,'判定表'!$B$3:$G$95,3,FALSE)),IF(OR($E15="KTN",$E15="WHZ"),(VLOOKUP($K15,'判定表'!$B$3:$G$95,4,FALSE)*I15),0))) | N15: =IF($I15="","",IF($K15="","",IF($G15=1,(VLOOKUP($F15,'金額'!$B$3:$J$114,3,FALSE)),0))) | O15: =IF(F15="","",(L15*I15+M15+N15)) | P15: =IF($K15="","",IF($E15="KTN",(VLOOKUP($K15,'判定表'!$B$3:$I$95,8,FALSE)),IF($I15="","",(VLOOKUP($F15,'金額'!$B$3:$J$114,9,FALSE)))))
B16: =IF($K16="","",(VLOOKUP($K16,'判定表'!$B$3:$G$105,6,FALSE))) | D16: =IF(C16="","",upper(TEXT(C16, "DDD"))) | E16: =IF(F16="","",VLOOKUP($F16,'金額'!$B$3:$K$44,10,FALSE)) | G16: =IF($F16="","",(VLOOKUP($F16,'金額'!$B$3:$E$114,2,FALSE))) | H16: =IF(F16="","",VLOOKUP($F16,'金額'!$B$3:$I$44,8,FALSE)) | I16: =IF(F16="","",VLOOKUP($F16,'金額'!$B$3:$I$44,7,FALSE)) | L16: =IF($I16="","",IF(AND($B16="K",$E16="KTN"),2000,IF(AND($B16="K",$E16="WHZ"),2000,IF($E16="MAHA",1500,IF($G16=0,(VLOOKUP($K16,'判定表'!$B$3:$G$96,2,FALSE)),0))))) | M16: =IF($K16="","",IF($E16="ANC",(VLOOKUP($K16,'判定表'!$B$3:$G$95,3,FALSE)),IF(OR($E16="KTN",$E16="WHZ"),(VLOOKUP($K16,'判定表'!$B$3:$G$95,4,FALSE)*I16),0))) | N16: =IF($I16="","",IF($K16="","",IF($G16=1,(VLOOKUP($F16,'金額'!$B$3:$J$114,3,FALSE)),0))) | O16: =IF(F16="","",(L16*I16+M16+N16)) | P16: =IF($K16="","",IF($E16="KTN",(VLOOKUP($K16,'判定表'!$B$3:$I$95,8,FALSE)),IF($I16="","",(VLOOKUP($F16,'金額'!$B$3:$J$114,9,FALSE)))))
B17: =IF($K17="","",(VLOOKUP($K17,'判定表'!$B$3:$G$105,6,FALSE))) | D17: =IF(C17="","",upper(TEXT(C17, "DDD"))) | E17: =IF(F17="","",VLOOKUP($F17,'金額'!$B$3:$K$44,10,FALSE)) | G17: =IF($F17="","",(VLOOKUP($F17,'金額'!$B$3:$E$114,2,FALSE))) | H17: =IF(F17="","",VLOOKUP($F17,'金額'!$B$3:$I$44,8,FALSE)) | I17: =IF(F17="","",VLOOKUP($F17,'金額'!$B$3:$I$44,7,FALSE)) | L17: =IF($I17="","",IF(AND($B17="K",$E17="KTN"),2000,IF(AND($B17="K",$E17="WHZ"),2000,IF($E17="MAHA",1500,IF($G17=0,(VLOOKUP($K17,'判定表'!$B$3:$G$96,2,FALSE)),0))))) | M17: =IF($K17="","",IF($E17="ANC",(VLOOKUP($K17,'判定表'!$B$3:$G$95,3,FALSE)),IF(OR($E17="KTN",$E17="WHZ"),(VLOOKUP($K17,'判定表'!$B$3:$G$95,4,FALSE)*I17),0))) | N17: =IF($I17="","",IF($K17="","",IF($G17=1,(VLOOKUP($F17,'金額'!$B$3:$J$114,3,FALSE)),0))) | O17: =IF(F17="","",(L17*I17+M17+N17)) | P17: =IF($K17="","",IF($E17="KTN",(VLOOKUP($K17,'判定表'!$B$3:$I$95,8,FALSE)),IF($I17="","",(VLOOKUP($F17,'金額'!$B$3:$J$114,9,FALSE)))))
B18: =IF($K18="","",(VLOOKUP($K18,'判定表'!$B$3:$G$105,6,FALSE))) | D18: =IF(C18="","",upper(TEXT(C18, "DDD"))) | E18: =IF(F18="","",VLOOKUP($F18,'金額'!$B$3:$K$44,10,FALSE)) | G18: =IF($F18="","",(VLOOKUP($F18,'金額'!$B$3:$E$114,2,FALSE))) | H18: =IF(F18="","",VLOOKUP($F18,'金額'!$B$3:$I$44,8,FALSE)) | I18: =IF(F18="","",VLOOKUP($F18,'金額'!$B$3:$I$44,7,FALSE)) | L18: =IF($I18="","",IF(AND($B18="K",$E18="KTN"),2000,IF(AND($B18="K",$E18="WHZ"),2000,IF($E18="MAHA",1500,IF($G18=0,(VLOOKUP($K18,'判定表'!$B$3:$G$96,2,FALSE)),0))))) | M18: =IF($K18="","",IF($E18="ANC",(VLOOKUP($K18,'判定表'!$B$3:$G$95,3,FALSE)),IF(OR($E18="KTN",$E18="WHZ"),(VLOOKUP($K18,'判定表'!$B$3:$G$95,4,FALSE)*I18),0))) | N18: =IF($I18="","",IF($K18="","",IF($G18=1,(VLOOKUP($F18,'金額'!$B$3:$J$114,3,FALSE)),0))) | O18: =IF(F18="","",(L18*I18+M18+N18)) | P18: =IF($K18="","",IF($E18="KTN",(VLOOKUP($K18,'判定表'!$B$3:$I$95,8,FALSE)),IF($I18="","",(VLOOKUP($F18,'金額'!$B$3:$J$114,9,FALSE)))))
B19: =IF($K19="","",(VLOOKUP($K19,'判定表'!$B$3:$G$105,6,FALSE))) | D19: =IF(C19="","",upper(TEXT(C19, "DDD"))) | E19: =IF(F19="","",VLOOKUP($F19,'金額'!$B$3:$K$44,10,FALSE)) | G19: =IF($F19="","",(VLOOKUP($F19,'金額'!$B$3:$E$114,2,FALSE))) | H19: =IF(F19="","",VLOOKUP($F19,'金額'!$B$3:$I$44,8,FALSE)) | I19: =IF(F19="","",VLOOKUP($F19,'金額'!$B$3:$I$44,7,FALSE)) | L19: =IF($I19="","",IF(AND($B19="K",$E19="KTN"),2000,IF(AND($B19="K",$E19="WHZ"),2000,IF($E19="MAHA",1500,IF($G19=0,(VLOOKUP($K19,'判定表'!$B$3:$G$96,2,FALSE)),0))))) | M19: =IF($K19="","",IF($E19="ANC",(VLOOKUP($K19,'判定表'!$B$3:$G$95,3,FALSE)),IF(OR($E19="KTN",$E19="WHZ"),(VLOOKUP($K19,'判定表'!$B$3:$G$95,4,FALSE)*I19),0))) | N19: =IF($I19="","",IF($K19="","",IF($G19=1,(VLOOKUP($F19,'金額'!$B$3:$J$114,3,FALSE)),0))) | O19: =IF(F19="","",(L19*I19+M19+N19)) | P19: =IF($K19="","",IF($E19="KTN",(VLOOKUP($K19,'判定表'!$B$3:$I$95,8,FALSE)),IF($I19="","",(VLOOKUP($F19,'金額'!$B$3:$J$114,9,FALSE)))))
... B411: =IF($K411="","",(VLOOKUP($K411,'判定表'!$B$3:$G$105,6,FALSE))) | D411: =IF(C411="","",upper(TEXT(C411, "DDD"))) | E411: =IF(F411="","",VLOOKUP($F411,'金額'!$B$3:$K$44,10,FALSE)) | G411: =IF($F411="","",(VLOOKUP($F411,'金額'!$B$3:$E$114,2,FALSE))) | H411: =IF(F411="","",VLOOKUP($F411,'金額'!$B$3:$I$44,8,FALSE)) | I411: =IF(F411="","",VLOOKUP($F411,'金額'!$B$3:$I$44,7,FALSE)) | L411: =IF($I411="","",IF(AND($B411="K",$E411="KTN"),2000,IF(AND($B411="K",$E411="WHZ"),2000,IF($E411="MAHA",1500,IF($G411=0,(VLOOKUP($K411,'判定表'!$B$3:$G$96,2,FALSE)),0))))) | M411: =IF($K411="","",IF($E411="ANC",(VLOOKUP($K411,'判定表'!$B$3:$G$95,3,FALSE)),IF(OR($E411="KTN",$E411="WHZ"),(VLOOKUP($K411,'判定表'!$B$3:$G$95,4,FALSE)*I411),0))) | N411: =IF($I411="","",IF($K411="","",IF($G411=1,(VLOOKUP($F411,'金額'!$B$3:$J$114,3,FALSE)),0))) | O411: =IF(F411="","",(L411*I411+M411+N411)) | P411: =IF($K411="","",IF($E411="KTN",(VLOOKUP($K411,'判定表'!$B$3:$I$95,8,FALSE)),IF($I411="","",(VLOOKUP($F411,'金額'!$B$3:$J$114,9,FALSE)))))
B412: =IF($K412="","",(VLOOKUP($K412,'判定表'!$B$3:$G$105,6,FALSE))) | D412: =IF(C412="","",upper(TEXT(C412, "DDD"))) | E412: =IF(F412="","",VLOOKUP($F412,'金額'!$B$3:$K$44,10,FALSE)) | G412: =IF($F412="","",(VLOOKUP($F412,'金額'!$B$3:$E$114,2,FALSE))) | H412: =IF(F412="","",VLOOKUP($F412,'金額'!$B$3:$I$44,8,FALSE)) | I412: =IF(F412="","",VLOOKUP($F412,'金額'!$B$3:$I$44,7,FALSE)) | L412: =IF($I412="","",IF(AND($B412="K",$E412="KTN"),2000,IF(AND($B412="K",$E412="WHZ"),2000,IF($E412="MAHA",1500,IF($G412=0,(VLOOKUP($K412,'判定表'!$B$3:$G$96,2,FALSE)),0))))) | M412: =IF($K412="","",IF($E412="ANC",(VLOOKUP($K412,'判定表'!$B$3:$G$95,3,FALSE)),IF(OR($E412="KTN",$E412="WHZ"),(VLOOKUP($K412,'判定表'!$B$3:$G$95,4,FALSE)*I412),0))) | N412: =IF($I412="","",IF($K412="","",IF($G412=1,(VLOOKUP($F412,'金額'!$B$3:$J$114,3,FALSE)),0))) | O412: =IF(F412="","",(L412*I412+M412+N412)) | P412: =IF($K412="","",IF($E412="KTN",(VLOOKUP($K412,'判定表'!$B$3:$I$95,8,FALSE)),IF($I412="","",(VLOOKUP($F412,'金額'!$B$3:$J$114,9,FALSE))))) | Q412: 要確認
B413: =IF($K413="","",(VLOOKUP($K413,'判定表'!$B$3:$G$105,6,FALSE))) | D413: =IF(C413="","",upper(TEXT(C413, "DDD"))) | E413: =IF(F413="","",VLOOKUP($F413,'金額'!$B$3:$K$44,10,FALSE)) | G413: =IF($F413="","",(VLOOKUP($F413,'金額'!$B$3:$E$114,2,FALSE))) | H413: =IF(F413="","",VLOOKUP($F413,'金額'!$B$3:$I$44,8,FALSE)) | I413: =IF(F413="","",VLOOKUP($F413,'金額'!$B$3:$I$44,7,FALSE)) | L413: =IF($I413="","",IF(AND($B413="K",$E413="KTN"),2000,IF(AND($B413="K",$E413="WHZ"),2000,IF($E413="MAHA",1500,IF($G413=0,(VLOOKUP($K413,'判定表'!$B$3:$G$96,2,FALSE)),0))))) | M413: =IF($K413="","",IF($E413="ANC",(VLOOKUP($K413,'判定表'!$B$3:$G$95,3,FALSE)),IF(OR($E413="KTN",$E413="WHZ"),(VLOOKUP($K413,'判定表'!$B$3:$G$95,4,FALSE)*I413),0))) | N413: =IF($I413="","",IF($K413="","",IF($G413=1,(VLOOKUP($F413,'金額'!$B$3:$J$114,3,FALSE)),0))) | O413: =IF(F413="","",(L413*I413+M413+N413)) | P413: =IF($K413="","",IF($E413="KTN",(VLOOKUP($K413,'判定表'!$B$3:$I$95,8,FALSE)),IF($I413="","",(VLOOKUP($F413,'金額'!$B$3:$J$114,9,FALSE)))))
B414: =IF($K414="","",(VLOOKUP($K414,'判定表'!$B$3:$G$105,6,FALSE))) | D414: =IF(C414="","",upper(TEXT(C414, "DDD"))) | E414: =IF(F414="","",VLOOKUP($F414,'金額'!$B$3:$K$44,10,FALSE)) | G414: =IF($F414="","",(VLOOKUP($F414,'金額'!$B$3:$E$114,2,FALSE))) | H414: =IF(F414="","",VLOOKUP($F414,'金額'!$B$3:$I$44,8,FALSE)) | I414: =IF(F414="","",VLOOKUP($F414,'金額'!$B$3:$I$44,7,FALSE)) | L414: =IF($I414="","",IF(AND($B414="K",$E414="KTN"),2000,IF(AND($B414="K",$E414="WHZ"),2000,IF($E414="MAHA",1500,IF($G414=0,(VLOOKUP($K414,'判定表'!$B$3:$G$96,2,FALSE)),0))))) | M414: =IF($K414="","",IF($E414="ANC",(VLOOKUP($K414,'判定表'!$B$3:$G$95,3,FALSE)),IF(OR($E414="KTN",$E414="WHZ"),(VLOOKUP($K414,'判定表'!$B$3:$G$95,4,FALSE)*I414),0))) | N414: =IF($I414="","",IF($K414="","",IF($G414=1,(VLOOKUP($F414,'金額'!$B$3:$J$114,3,FALSE)),0))) | O414: =IF(F414="","",(L414*I414+M414+N414)) | P414: =IF($K414="","",IF($E414="KTN",(VLOOKUP($K414,'判定表'!$B$3:$I$95,8,FALSE)),IF($I414="","",(VLOOKUP($F414,'金額'!$B$3:$J$114,9,FALSE)))))
B415: =IF($K415="","",(VLOOKUP($K415,'判定表'!$B$3:$G$105,6,FALSE))) | D415: =IF(C415="","",upper(TEXT(C415, "DDD"))) | E415: =IF(F415="","",VLOOKUP($F415,'金額'!$B$3:$K$44,10,FALSE)) | G415: =IF($F415="","",(VLOOKUP($F415,'金額'!$B$3:$E$114,2,FALSE))) | H415: =IF(F415="","",VLOOKUP($F415,'金額'!$B$3:$I$44,8,FALSE)) | I415: =IF(F415="","",VLOOKUP($F415,'金額'!$B$3:$I$44,7,FALSE)) | L415: =IF($I415="","",IF(AND($B415="K",$E415="KTN"),2000,IF(AND($B415="K",$E415="WHZ"),2000,IF($E415="MAHA",1500,IF($G415=0,(VLOOKUP($K415,'判定表'!$B$3:$G$96,2,FALSE)),0))))) | M415: =IF($K415="","",IF($E415="ANC",(VLOOKUP($K415,'判定表'!$B$3:$G$95,3,FALSE)),IF(OR($E415="KTN",$E415="WHZ"),(VLOOKUP($K415,'判定表'!$B$3:$G$95,4,FALSE)*I415),0))) | N415: =IF($I415="","",IF($K415="","",IF($G415=1,(VLOOKUP($F415,'金額'!$B$3:$J$114,3,FALSE)),0))) | O415: =IF(F415="","",(L415*I415+M415+N415)) | P415: =IF($K415="","",IF($E415="KTN",(VLOOKUP($K415,'判定表'!$B$3:$I$95,8,FALSE)),IF($I415="","",(VLOOKUP($F415,'金額'!$B$3:$J$114,9,FALSE)))))
B416: =IF($K416="","",(VLOOKUP($K416,'判定表'!$B$3:$G$105,6,FALSE))) | D416: =IF(C416="","",upper(TEXT(C416, "DDD"))) | E416: =IF(F416="","",VLOOKUP($F416,'金額'!$B$3:$K$44,10,FALSE)) | G416: =IF($F416="","",(VLOOKUP($F416,'金額'!$B$3:$E$114,2,FALSE))) | H416: =IF(F416="","",VLOOKUP($F416,'金額'!$B$3:$I$44,8,FALSE)) | I416: =IF(F416="","",VLOOKUP($F416,'金額'!$B$3:$I$44,7,FALSE)) | L416: =IF($I416="","",IF(AND($B416="K",$E416="KTN"),2000,IF(AND($B416="K",$E416="WHZ"),2000,IF($E416="MAHA",1500,IF($G416=0,(VLOOKUP($K416,'判定表'!$B$3:$G$96,2,FALSE)),0))))) | M416: =IF($K416="","",IF($E416="ANC",(VLOOKUP($K416,'判定表'!$B$3:$G$95,3,FALSE)),IF(OR($E416="KTN",$E416="WHZ"),(VLOOKUP($K416,'判定表'!$B$3:$G$95,4,FALSE)*I416),0))) | N416: =IF($I416="","",IF($K416="","",IF($G416=1,(VLOOKUP($F416,'金額'!$B$3:$J$114,3,FALSE)),0))) | O416: =IF(F416="","",(L416*I416+M416+N416)) | P416: =IF($K416="","",IF($E416="KTN",(VLOOKUP($K416,'判定表'!$B$3:$I$95,8,FALSE)),IF($I416="","",(VLOOKUP($F416,'金額'!$B$3:$J$114,9,FALSE)))))
B417: =IF($K417="","",(VLOOKUP($K417,'判定表'!$B$3:$G$105,6,FALSE))) | D417: =IF(C417="","",upper(TEXT(C417, "DDD"))) | E417: =IF(F417="","",VLOOKUP($F417,'金額'!$B$3:$K$44,10,FALSE)) | G417: =IF($F417="","",(VLOOKUP($F417,'金額'!$B$3:$E$114,2,FALSE))) | H417: =IF(F417="","",VLOOKUP($F417,'金額'!$B$3:$I$44,8,FALSE)) | I417: =IF(F417="","",VLOOKUP($F417,'金額'!$B$3:$I$44,7,FALSE)) | L417: =IF($I417="","",IF(AND($B417="K",$E417="KTN"),2000,IF(AND($B417="K",$E417="WHZ"),2000,IF($E417="MAHA",1500,IF($G417=0,(VLOOKUP($K417,'判定表'!$B$3:$G$96,2,FALSE)),0))))) | M417: =IF($K417="","",IF($E417="ANC",(VLOOKUP($K417,'判定表'!$B$3:$G$95,3,FALSE)),IF(OR($E417="KTN",$E417="WHZ"),(VLOOKUP($K417,'判定表'!$B$3:$G$95,4,FALSE)*I417),0))) | N417: =IF($I417="","",IF($K417="","",IF($G417=1,(VLOOKUP($F417,'金額'!$B$3:$J$114,3,FALSE)),0))) | O417: =IF(F417="","",(L417*I417+M417+N417)) | P417: =IF($K417="","",IF($E417="KTN",(VLOOKUP($K417,'判定表'!$B$3:$I$95,8,FALSE)),IF($I417="","",(VLOOKUP($F417,'金額'!$B$3:$J$114,9,FALSE)))))
B418: =IF($K418="","",(VLOOKUP($K418,'判定表'!$B$3:$G$105,6,FALSE))) | D418: =IF(C418="","",upper(TEXT(C418, "DDD"))) | E418: =IF(F418="","",VLOOKUP($F418,'金額'!$B$3:$K$44,10,FALSE)) | G418: =IF($F418="","",(VLOOKUP($F418,'金額'!$B$3:$E$114,2,FALSE))) | H418: =IF(F418="","",VLOOKUP($F418,'金額'!$B$3:$I$44,8,FALSE)) | I418: =IF(F418="","",VLOOKUP($F418,'金額'!$B$3:$I$44,7,FALSE)) | L418: =IF($I418="","",IF(AND($B418="K",$E418="KTN"),2000,IF(AND($B418="K",$E418="WHZ"),2000,IF($E418="MAHA",1500,IF($G418=0,(VLOOKUP($K418,'判定表'!$B$3:$G$96,2,FALSE)),0))))) | M418: =IF($K418="","",IF($E418="ANC",(VLOOKUP($K418,'判定表'!$B$3:$G$95,3,FALSE)),IF(OR($E418="KTN",$E418="WHZ"),(VLOOKUP($K418,'判定表'!$B$3:$G$95,4,FALSE)*I418),0))) | N418: =IF($I418="","",IF($K418="","",IF($G418=1,(VLOOKUP($F418,'金額'!$B$3:$J$114,3,FALSE)),0))) | O418: =IF(F418="","",(L418*I418+M418+N418)) | P418: =IF($K418="","",IF($E418="KTN",(VLOOKUP($K418,'判定表'!$B$3:$I$95,8,FALSE)),IF($I418="","",(VLOOKUP($F418,'金額'!$B$3:$J$114,9,FALSE)))))
B419: =IF($K419="","",(VLOOKUP($K419,'判定表'!$B$3:$G$105,6,FALSE))) | D419: =IF(C419="","",upper(TEXT(C419, "DDD"))) | E419: =IF(F419="","",VLOOKUP($F419,'金額'!$B$3:$K$44,10,FALSE)) | G419: =IF($F419="","",(VLOOKUP($F419,'金額'!$B$3:$E$114,2,FALSE))) | H419: =IF(F419="","",VLOOKUP($F419,'金額'!$B$3:$I$44,8,FALSE)) | I419: =IF(F419="","",VLOOKUP($F419,'金額'!$B$3:$I$44,7,FALSE)) | L419: =IF($I419="","",IF(AND($B419="K",$E419="KTN"),2000,IF(AND($B419="K",$E419="WHZ"),2000,IF($E419="MAHA",1500,IF($G419=0,(VLOOKUP($K419,'判定表'!$B$3:$G$96,2,FALSE)),0))))) | M419: =IF($K419="","",IF($E419="ANC",(VLOOKUP($K419,'判定表'!$B$3:$G$95,3,FALSE)),IF(OR($E419="KTN",$E419="WHZ"),(VLOOKUP($K419,'判定表'!$B$3:$G$95,4,FALSE)*I419),0))) | N419: =IF($I419="","",IF($K419="","",IF($G419=1,(VLOOKUP($F419,'金額'!$B$3:$J$114,3,FALSE)),0))) | O419: =IF(F419="","",(L419*I419+M419+N419)) | P419: =IF($K419="","",IF($E419="KTN",(VLOOKUP($K419,'判定表'!$B$3:$I$95,8,FALSE)),IF($I419="","",(VLOOKUP($F419,'金額'!$B$3:$J$114,9,FALSE)))))
B420: =IF($K420="","",(VLOOKUP($K420,'判定表'!$B$3:$G$105,6,FALSE))) | D420: =IF(C420="","",upper(TEXT(C420, "DDD"))) | E420: =IF(F420="","",VLOOKUP($F420,'金額'!$B$3:$K$44,10,FALSE)) | G420: =IF($F420="","",(VLOOKUP($F420,'金額'!$B$3:$E$114,2,FALSE))) | H420: =IF(F420="","",VLOOKUP($F420,'金額'!$B$3:$I$44,8,FALSE)) | I420: =IF(F420="","",VLOOKUP($F420,'金額'!$B$3:$I$44,7,FALSE)) | L420: =IF($I420="","",IF(AND($B420="K",$E420="KTN"),2000,IF(AND($B420="K",$E420="WHZ"),2000,IF($E420="MAHA",1500,IF($G420=0,(VLOOKUP($K420,'判定表'!$B$3:$G$96,2,FALSE)),0))))) | M420: =IF($K420="","",IF($E420="ANC",(VLOOKUP($K420,'判定表'!$B$3:$G$95,3,FALSE)),IF(OR($E420="KTN",$E420="WHZ"),(VLOOKUP($K420,'判定表'!$B$3:$G$95,4,FALSE)*I420),0))) | N420: =IF($I420="","",IF($K420="","",IF($G420=1,(VLOOKUP($F420,'金額'!$B$3:$J$114,3,FALSE)),0))) | O420: =IF(F420="","",(L420*I420+M420+N420)) | P420: =IF($K420="","",IF($E420="KTN",(VLOOKUP($K420,'判定表'!$B$3:$I$95,8,FALSE)),IF($I420="","",(VLOOKUP($F420,'金額'!$B$3:$J$114,9,FALSE)))))
B421: =IF($K421="","",(VLOOKUP($K421,'判定表'!$B$3:$G$105,6,FALSE))) | D421: =IF(C421="","",upper(TEXT(C421, "DDD"))) | E421: =IF(F421="","",VLOOKUP($F421,'金額'!$B$3:$K$44,10,FALSE)) | G421: =IF($F421="","",(VLOOKUP($F421,'金額'!$B$3:$E$114,2,FALSE))) | H421: =IF(F421="","",VLOOKUP($F421,'金額'!$B$3:$I$44,8,FALSE)) | I421: =IF(F421="","",VLOOKUP($F421,'金額'!$B$3:$I$44,7,FALSE)) | L421: =IF($I421="","",IF(AND($B421="K",$E421="KTN"),2000,IF(AND($B421="K",$E421="WHZ"),2000,IF($E421="MAHA",1500,IF($G421=0,(VLOOKUP($K421,'判定表'!$B$3:$G$96,2,FALSE)),0))))) | M421: =IF($K421="","",IF($E421="ANC",(VLOOKUP($K421,'判定表'!$B$3:$G$95,3,FALSE)),IF(OR($E421="KTN",$E421="WHZ"),(VLOOKUP($K421,'判定表'!$B$3:$G$95,4,FALSE)*I421),0))) | N421: =IF($I421="","",IF($K421="","",IF($G421=1,(VLOOKUP($F421,'金額'!$B$3:$J$114,3,FALSE)),0))) | O421: =IF(F421="","",(L421*I421+M421+N421)) | P421: =IF($K421="","",IF($E421="KTN",(VLOOKUP($K421,'判定表'!$B$3:$I$95,8,FALSE)),IF($I421="","",(VLOOKUP($F421,'金額'!$B$3:$J$114,9,FALSE)))))
B422: =IF($K422="","",(VLOOKUP($K422,'判定表'!$B$3:$G$105,6,FALSE))) | D422: =IF(C422="","",upper(TEXT(C422, "DDD"))) | E422: =IF(F422="","",VLOOKUP($F422,'金額'!$B$3:$K$44,10,FALSE)) | G422: =IF($F422="","",(VLOOKUP($F422,'金額'!$B$3:$E$114,2,FALSE))) | H422: =IF(F422="","",VLOOKUP($F422,'金額'!$B$3:$I$44,8,FALSE)) | I422: =IF(F422="","",VLOOKUP($F422,'金額'!$B$3:$I$44,7,FALSE)) | L422: =IF($I422="","",IF(AND($B422="K",$E422="KTN"),2000,IF(AND($B422="K",$E422="WHZ"),2000,IF($E422="MAHA",1500,IF($G422=0,(VLOOKUP($K422,'判定表'!$B$3:$G$96,2,FALSE)),0))))) | M422: =IF($K422="","",IF($E422="ANC",(VLOOKUP($K422,'判定表'!$B$3:$G$95,3,FALSE)),IF(OR($E422="KTN",$E422="WHZ"),(VLOOKUP($K422,'判定表'!$B$3:$G$95,4,FALSE)*I422),0))) | N422: =IF($I422="","",IF($K422="","",IF($G422=1,(VLOOKUP($F422,'金額'!$B$3:$J$114,3,FALSE)),0))) | O422: =IF(F422="","",(L422*I422+M422+N422)) | P422: =IF($K422="","",IF($E422="KTN",(VLOOKUP($K422,'判定表'!$B$3:$I$95,8,FALSE)),IF($I422="","",(VLOOKUP($F422,'金額'!$B$3:$J$114,9,FALSE)))))
B423: =IF($K423="","",(VLOOKUP($K423,'判定表'!$B$3:$G$105,6,FALSE))) | D423: =IF(C423="","",upper(TEXT(C423, "DDD"))) | E423: =IF(F423="","",VLOOKUP($F423,'金額'!$B$3:$K$44,10,FALSE)) | G423: =IF($F423="","",(VLOOKUP($F423,'金額'!$B$3:$E$114,2,FALSE))) | H423: =IF(F423="","",VLOOKUP($F423,'金額'!$B$3:$I$44,8,FALSE)) | I423: =IF(F423="","",VLOOKUP($F423,'金額'!$B$3:$I$44,7,FALSE)) | L423: =IF($I423="","",IF(AND($B423="K",$E423="KTN"),2000,IF(AND($B423="K",$E423="WHZ"),2000,IF($E423="MAHA",1500,IF($G423=0,(VLOOKUP($K423,'判定表'!$B$3:$G$96,2,FALSE)),0))))) | M423: =IF($K423="","",IF($E423="ANC",(VLOOKUP($K423,'判定表'!$B$3:$G$95,3,FALSE)),IF(OR($E423="KTN",$E423="WHZ"),(VLOOKUP($K423,'判定表'!$B$3:$G$95,4,FALSE)*I423),0))) | N423: =IF($I423="","",IF($K423="","",IF($G423=1,(VLOOKUP($F423,'金額'!$B$3:$J$114,3,FALSE)),0))) | O423: =IF(F423="","",(L423*I423+M423+N423)) | P423: =IF($K423="","",IF($E423="KTN",(VLOOKUP($K423,'判定表'!$B$3:$I$95,8,FALSE)),IF($I423="","",(VLOOKUP($F423,'金額'!$B$3:$J$114,9,FALSE)))))
B424: =IF($K424="","",(VLOOKUP($K424,'判定表'!$B$3:$G$105,6,FALSE))) | D424: =IF(C424="","",upper(TEXT(C424, "DDD"))) | E424: =IF(F424="","",VLOOKUP($F424,'金額'!$B$3:$K$44,10,FALSE)) | G424: =IF($F424="","",(VLOOKUP($F424,'金額'!$B$3:$E$114,2,FALSE))) | H424: =IF(F424="","",VLOOKUP($F424,'金額'!$B$3:$I$44,8,FALSE)) | I424: =IF(F424="","",VLOOKUP($F424,'金額'!$B$3:$I$44,7,FALSE)) | L424: =IF($I424="","",IF(AND($B424="K",$E424="KTN"),2000,IF(AND($B424="K",$E424="WHZ"),2000,IF($E424="MAHA",1500,IF($G424=0,(VLOOKUP($K424,'判定表'!$B$3:$G$96,2,FALSE)),0))))) | M424: =IF($K424="","",IF($E424="ANC",(VLOOKUP($K424,'判定表'!$B$3:$G$95,3,FALSE)),IF(OR($E424="KTN",$E424="WHZ"),(VLOOKUP($K424,'判定表'!$B$3:$G$95,4,FALSE)*I424),0))) | N424: =IF($I424="","",IF($K424="","",IF($G424=1,(VLOOKUP($F424,'金額'!$B$3:$J$114,3,FALSE)),0))) | O424: =IF(F424="","",(L424*I424+M424+N424)) | P424: =IF($K424="","",IF($E424="KTN",(VLOOKUP($K424,'判定表'!$B$3:$I$95,8,FALSE)),IF($I424="","",(VLOOKUP($F424,'金額'!$B$3:$J$114,9,FALSE)))))
... B594: =IF($K594="","",(VLOOKUP($K594,'判定表'!$B$3:$G$105,6,FALSE))) | D594: =IF(C594="","",upper(TEXT(C594, "DDD"))) | E594: =IF(F594="","",VLOOKUP($F594,'金額'!$B$3:$K$44,10,FALSE)) | G594: =IF($F594="","",(VLOOKUP($F594,'金額'!$B$3:$E$114,2,FALSE))) | H594: =IF(F594="","",VLOOKUP($F594,'金額'!$B$3:$I$44,8,FALSE)) | I594: =IF(F594="","",VLOOKUP($F594,'金額'!$B$3:$I$44,7,FALSE)) | L594: =IF($I594="","",IF(AND($B594="K",$E594="KTN"),2000,IF(AND($B594="K",$E594="WHZ"),2000,IF($E594="MAHA",1500,IF($G594=0,(VLOOKUP($K594,'判定表'!$B$3:$G$96,2,FALSE)),0))))) | M594: =IF($K594="","",IF($E594="ANC",(VLOOKUP($K594,'判定表'!$B$3:$G$95,3,FALSE)),IF(OR($E594="KTN",$E594="WHZ"),(VLOOKUP($K594,'判定表'!$B$3:$G$95,4,FALSE)*I594),0))) | N594: =IF($I594="","",IF($K594="","",IF($G594=1,(VLOOKUP($F594,'金額'!$B$3:$J$114,3,FALSE)),0))) | O594: =IF(F594="","",(L594*I594+M594+N594)) | P594: =IF($K594="","",IF($E594="KTN",(VLOOKUP($K594,'判定表'!$B$3:$I$95,8,FALSE)),IF($I594="","",(VLOOKUP($F594,'金額'!$B$3:$J$114,9,FALSE)))))
B595: =IF($K595="","",(VLOOKUP($K595,'判定表'!$B$3:$G$105,6,FALSE))) | D595: =IF(C595="","",upper(TEXT(C595, "DDD"))) | E595: =IF(F595="","",VLOOKUP($F595,'金額'!$B$3:$K$44,10,FALSE)) | G595: =IF($F595="","",(VLOOKUP($F595,'金額'!$B$3:$E$114,2,FALSE))) | H595: =IF(F595="","",VLOOKUP($F595,'金額'!$B$3:$I$44,8,FALSE)) | I595: =IF(F595="","",VLOOKUP($F595,'金額'!$B$3:$I$44,7,FALSE)) | L595: =IF($I595="","",IF(AND($B595="K",$E595="KTN"),2000,IF(AND($B595="K",$E595="WHZ"),2000,IF($E595="MAHA",1500,IF($G595=0,(VLOOKUP($K595,'判定表'!$B$3:$G$96,2,FALSE)),0))))) | M595: =IF($K595="","",IF($E595="ANC",(VLOOKUP($K595,'判定表'!$B$3:$G$95,3,FALSE)),IF(OR($E595="KTN",$E595="WHZ"),(VLOOKUP($K595,'判定表'!$B$3:$G$95,4,FALSE)*I595),0))) | N595: =IF($I595="","",IF($K595="","",IF($G595=1,(VLOOKUP($F595,'金額'!$B$3:$J$114,3,FALSE)),0))) | O595: =IF(F595="","",(L595*I595+M595+N595)) | P595: =IF($K595="","",IF($E595="KTN",(VLOOKUP($K595,'判定表'!$B$3:$I$95,8,FALSE)),IF($I595="","",(VLOOKUP($F595,'金額'!$B$3:$J$114,9,FALSE))))) | Q595: タクシー代確認
B596: =IF($K596="","",(VLOOKUP($K596,'判定表'!$B$3:$G$105,6,FALSE))) | D596: =IF(C596="","",upper(TEXT(C596, "DDD"))) | E596: =IF(F596="","",VLOOKUP($F596,'金額'!$B$3:$K$44,10,FALSE)) | G596: =IF($F596="","",(VLOOKUP($F596,'金額'!$B$3:$E$114,2,FALSE))) | H596: =IF(F596="","",VLOOKUP($F596,'金額'!$B$3:$I$44,8,FALSE)) | I596: =IF(F596="","",VLOOKUP($F596,'金額'!$B$3:$I$44,7,FALSE)) | L596: =IF($I596="","",IF(AND($B596="K",$E596="KTN"),2000,IF(AND($B596="K",$E596="WHZ"),2000,IF($E596="MAHA",1500,IF($G596=0,(VLOOKUP($K596,'判定表'!$B$3:$G$96,2,FALSE)),0))))) | M596: =IF($K596="","",IF($E596="ANC",(VLOOKUP($K596,'判定表'!$B$3:$G$95,3,FALSE)),IF(OR($E596="KTN",$E596="WHZ"),(VLOOKUP($K596,'判定表'!$B$3:$G$95,4,FALSE)*I596),0))) | N596: =IF($I596="","",IF($K596="","",IF($G596=1,(VLOOKUP($F596,'金額'!$B$3:$J$114,3,FALSE)),0))) | O596: =IF(F596="","",(L596*I596+M596+N596)) | P596: =IF($K596="","",IF($E596="KTN",(VLOOKUP($K596,'判定表'!$B$3:$I$95,8,FALSE)),IF($I596="","",(VLOOKUP($F596,'金額'!$B$3:$J$114,9,FALSE)))))
B597: =IF($K597="","",(VLOOKUP($K597,'判定表'!$B$3:$G$105,6,FALSE))) | D597: =IF(C597="","",upper(TEXT(C597, "DDD"))) | E597: =IF(F597="","",VLOOKUP($F597,'金額'!$B$3:$K$44,10,FALSE)) | G597: =IF($F597="","",(VLOOKUP($F597,'金額'!$B$3:$E$114,2,FALSE))) | H597: =IF(F597="","",VLOOKUP($F597,'金額'!$B$3:$I$44,8,FALSE)) | I597: =IF(F597="","",VLOOKUP($F597,'金額'!$B$3:$I$44,7,FALSE)) | L597: =IF($I597="","",IF(AND($B597="K",$E597="KTN"),2000,IF(AND($B597="K",$E597="WHZ"),2000,IF($E597="MAHA",1500,IF($G597=0,(VLOOKUP($K597,'判定表'!$B$3:$G$96,2,FALSE)),0))))) | M597: =IF($K597="","",IF($E597="ANC",(VLOOKUP($K597,'判定表'!$B$3:$G$95,3,FALSE)),IF(OR($E597="KTN",$E597="WHZ"),(VLOOKUP($K597,'判定表'!$B$3:$G$95,4,FALSE)*I597),0))) | N597: =IF($I597="","",IF($K597="","",IF($G597=1,(VLOOKUP($F597,'金額'!$B$3:$J$114,3,FALSE)),0))) | O597: =IF(F597="","",(L597*I597+M597+N597)) | P597: =IF($K597="","",IF($E597="KTN",(VLOOKUP($K597,'判定表'!$B$3:$I$95,8,FALSE)),IF($I597="","",(VLOOKUP($F597,'金額'!$B$3:$J$114,9,FALSE)))))
B598: =IF($K598="","",(VLOOKUP($K598,'判定表'!$B$3:$G$105,6,FALSE))) | D598: =IF(C598="","",upper(TEXT(C598, "DDD"))) | E598: =IF(F598="","",VLOOKUP($F598,'金額'!$B$3:$K$44,10,FALSE)) | G598: =IF($F598="","",(VLOOKUP($F598,'金額'!$B$3:$E$114,2,FALSE))) | H598: =IF(F598="","",VLOOKUP($F598,'金額'!$B$3:$I$44,8,FALSE)) | I598: =IF(F598="","",VLOOKUP($F598,'金額'!$B$3:$I$44,7,FALSE)) | L598: =IF($I598="","",IF(AND($B598="K",$E598="KTN"),2000,IF(AND($B598="K",$E598="WHZ"),2000,IF($E598="MAHA",1500,IF($G598=0,(VLOOKUP($K598,'判定表'!$B$3:$G$96,2,FALSE)),0))))) | M598: =IF($K598="","",IF($E598="ANC",(VLOOKUP($K598,'判定表'!$B$3:$G$95,3,FALSE)),IF(OR($E598="KTN",$E598="WHZ"),(VLOOKUP($K598,'判定表'!$B$3:$G$95,4,FALSE)*I598),0))) | N598: =IF($I598="","",IF($K598="","",IF($G598=1,(VLOOKUP($F598,'金額'!$B$3:$J$114,3,FALSE)),0))) | O598: =IF(F598="","",(L598*I598+M598+N598)) | P598: =IF($K598="","",IF($E598="KTN",(VLOOKUP($K598,'判定表'!$B$3:$I$95,8,FALSE)),IF($I598="","",(VLOOKUP($F598,'金額'!$B$3:$J$114,9,FALSE)))))
B599: =IF($K599="","",(VLOOKUP($K599,'判定表'!$B$3:$G$105,6,FALSE))) | D599: =IF(C599="","",upper(TEXT(C599, "DDD"))) | E599: =IF(F599="","",VLOOKUP($F599,'金額'!$B$3:$K$44,10,FALSE)) | G599: =IF($F599="","",(VLOOKUP($F599,'金額'!$B$3:$E$114,2,FALSE))) | H599: =IF(F599="","",VLOOKUP($F599,'金額'!$B$3:$I$44,8,FALSE)) | I599: =IF(F599="","",VLOOKUP($F599,'金額'!$B$3:$I$44,7,FALSE)) | L599: =IF($I599="","",IF(AND($B599="K",$E599="KTN"),2000,IF(AND($B599="K",$E599="WHZ"),2000,IF($E599="MAHA",1500,IF($G599=0,(VLOOKUP($K599,'判定表'!$B$3:$G$96,2,FALSE)),0))))) | M599: =IF($K599="","",IF($E599="ANC",(VLOOKUP($K599,'判定表'!$B$3:$G$95,3,FALSE)),IF(OR($E599="KTN",$E599="WHZ"),(VLOOKUP($K599,'判定表'!$B$3:$G$95,4,FALSE)*I599),0))) | N599: =IF($I599="","",IF($K599="","",IF($G599=1,(VLOOKUP($F599,'金額'!$B$3:$J$114,3,FALSE)),0))) | O599: =IF(F599="","",(L599*I599+M599+N599)) | P599: =IF($K599="","",IF($E599="KTN",(VLOOKUP($K599,'判定表'!$B$3:$I$95,8,FALSE)),IF($I599="","",(VLOOKUP($F599,'金額'!$B$3:$J$114,9,FALSE)))))
B600: =IF($K600="","",(VLOOKUP($K600,'判定表'!$B$3:$G$105,6,FALSE))) | D600: =IF(C600="","",upper(TEXT(C600, "DDD"))) | E600: =IF(F600="","",VLOOKUP($F600,'金額'!$B$3:$K$44,10,FALSE)) | G600: =IF($F600="","",(VLOOKUP($F600,'金額'!$B$3:$E$114,2,FALSE))) | H600: =IF(F600="","",VLOOKUP($F600,'金額'!$B$3:$I$44,8,FALSE)) | I600: =IF(F600="","",VLOOKUP($F600,'金額'!$B$3:$I$44,7,FALSE)) | L600: =IF($I600="","",IF(AND($B600="K",$E600="KTN"),2000,IF(AND($B600="K",$E600="WHZ"),2000,IF($E600="MAHA",1500,IF($G600=0,(VLOOKUP($K600,'判定表'!$B$3:$G$96,2,FALSE)),0))))) | M600: =IF($K600="","",IF($E600="ANC",(VLOOKUP($K600,'判定表'!$B$3:$G$95,3,FALSE)),IF(OR($E600="KTN",$E600="WHZ"),(VLOOKUP($K600,'判定表'!$B$3:$G$95,4,FALSE)*I600),0))) | N600: =IF($I600="","",IF($K600="","",IF($G600=1,(VLOOKUP($F600,'金額'!$B$3:$J$114,3,FALSE)),0))) | O600: =IF(F600="","",(L600*I600+M600+N600)) | P600: =IF($K600="","",IF($E600="KTN",(VLOOKUP($K600,'判定表'!$B$3:$I$95,8,FALSE)),IF($I600="","",(VLOOKUP($F600,'金額'!$B$3:$J$114,9,FALSE)))))
B601: =IF($K601="","",(VLOOKUP($K601,'判定表'!$B$3:$G$105,6,FALSE))) | D601: =IF(C601="","",upper(TEXT(C601, "DDD"))) | E601: =IF(F601="","",VLOOKUP($F601,'金額'!$B$3:$K$44,10,FALSE)) | G601: =IF($F601="","",(VLOOKUP($F601,'金額'!$B$3:$E$114,2,FALSE))) | H601: =IF(F601="","",VLOOKUP($F601,'金額'!$B$3:$I$44,8,FALSE)) | I601: =IF(F601="","",VLOOKUP($F601,'金額'!$B$3:$I$44,7,FALSE)) | L601: =IF($I601="","",IF(AND($B601="K",$E601="KTN"),2000,IF(AND($B601="K",$E601="WHZ"),2000,IF($E601="MAHA",1500,IF($G601=0,(VLOOKUP($K601,'判定表'!$B$3:$G$96,2,FALSE)),0))))) | M601: =IF($K601="","",IF($E601="ANC",(VLOOKUP($K601,'判定表'!$B$3:$G$95,3,FALSE)),IF(OR($E601="KTN",$E601="WHZ"),(VLOOKUP($K601,'判定表'!$B$3:$G$95,4,FALSE)*I601),0))) | N601: =IF($I601="","",IF($K601="","",IF($G601=1,(VLOOKUP($F601,'金額'!$B$3:$J$114,3,FALSE)),0))) | O601: =IF(F601="","",(L601*I601+M601+N601)) | P601: =IF($K601="","",IF($E601="KTN",(VLOOKUP($K601,'判定表'!$B$3:$I$95,8,FALSE)),IF($I601="","",(VLOOKUP($F601,'金額'!$B$3:$J$114,9,FALSE)))))
B602: =IF($K602="","",(VLOOKUP($K602,'判定表'!$B$3:$G$105,6,FALSE))) | D602: =IF(C602="","",upper(TEXT(C602, "DDD"))) | E602: =IF(F602="","",VLOOKUP($F602,'金額'!$B$3:$K$44,10,FALSE)) | G602: =IF($F602="","",(VLOOKUP($F602,'金額'!$B$3:$E$114,2,FALSE))) | H602: =IF(F602="","",VLOOKUP($F602,'金額'!$B$3:$I$44,8,FALSE)) | I602: =IF(F602="","",VLOOKUP($F602,'金額'!$B$3:$I$44,7,FALSE)) | L602: =IF($I602="","",IF(AND($B602="K",$E602="KTN"),2000,IF(AND($B602="K",$E602="WHZ"),2000,IF($E602="MAHA",1500,IF($G602=0,(VLOOKUP($K602,'判定表'!$B$3:$G$96,2,FALSE)),0))))) | M602: =IF($K602="","",IF($E602="ANC",(VLOOKUP($K602,'判定表'!$B$3:$G$95,3,FALSE)),IF(OR($E602="KTN",$E602="WHZ"),(VLOOKUP($K602,'判定表'!$B$3:$G$95,4,FALSE)*I602),0))) | N602: =IF($I602="","",IF($K602="","",IF($G602=1,(VLOOKUP($F602,'金額'!$B$3:$J$114,3,FALSE)),0))) | O602: =IF(F602="","",(L602*I602+M602+N602)) | P602: =IF($K602="","",IF($E602="KTN",(VLOOKUP($K602,'判定表'!$B$3:$I$95,8,FALSE)),IF($I602="","",(VLOOKUP($F602,'金額'!$B$3:$J$114,9,FALSE)))))
B603: =IF($K603="","",(VLOOKUP($K603,'判定表'!$B$3:$G$105,6,FALSE))) | D603: =IF(C603="","",upper(TEXT(C603, "DDD"))) | E603: =IF(F603="","",VLOOKUP($F603,'金額'!$B$3:$K$44,10,FALSE)) | G603: =IF($F603="","",(VLOOKUP($F603,'金額'!$B$3:$E$114,2,FALSE))) | H603: =IF(F603="","",VLOOKUP($F603,'金額'!$B$3:$I$44,8,FALSE)) | I603: =IF(F603="","",VLOOKUP($F603,'金額'!$B$3:$I$44,7,FALSE)) | L603: =IF($I603="","",IF(AND($B603="K",$E603="KTN"),2000,IF(AND($B603="K",$E603="WHZ"),2000,IF($E603="MAHA",1500,IF($G603=0,(VLOOKUP($K603,'判定表'!$B$3:$G$96,2,FALSE)),0))))) | M603: =IF($K603="","",IF($E603="ANC",(VLOOKUP($K603,'判定表'!$B$3:$G$95,3,FALSE)),IF(OR($E603="KTN",$E603="WHZ"),(VLOOKUP($K603,'判定表'!$B$3:$G$95,4,FALSE)*I603),0))) | N603: =IF($I603="","",IF($K603="","",IF($G603=1,(VLOOKUP($F603,'金額'!$B$3:$J$114,3,FALSE)),0))) | O603: =IF(F603="","",(L603*I603+M603+N603)) | P603: =IF($K603="","",IF($E603="KTN",(VLOOKUP($K603,'判定表'!$B$3:$I$95,8,FALSE)),IF($I603="","",(VLOOKUP($F603,'金額'!$B$3:$J$114,9,FALSE)))))
B604: =IF($K604="","",(VLOOKUP($K604,'判定表'!$B$3:$G$105,6,FALSE))) | D604: =IF(C604="","",upper(TEXT(C604, "DDD"))) | E604: =IF(F604="","",VLOOKUP($F604,'金額'!$B$3:$K$44,10,FALSE)) | G604: =IF($F604="","",(VLOOKUP($F604,'金額'!$B$3:$E$114,2,FALSE))) | H604: =IF(F604="","",VLOOKUP($F604,'金額'!$B$3:$I$44,8,FALSE)) | I604: =IF(F604="","",VLOOKUP($F604,'金額'!$B$3:$I$44,7,FALSE)) | L604: =IF($I604="","",IF(AND($B604="K",$E604="KTN"),2000,IF(AND($B604="K",$E604="WHZ"),2000,IF($E604="MAHA",1500,IF($G604=0,(VLOOKUP($K604,'判定表'!$B$3:$G$96,2,FALSE)),0))))) | M604: =IF($K604="","",IF($E604="ANC",(VLOOKUP($K604,'判定表'!$B$3:$G$95,3,FALSE)),IF(OR($E604="KTN",$E604="WHZ"),(VLOOKUP($K604,'判定表'!$B$3:$G$95,4,FALSE)*I604),0))) | N604: =IF($I604="","",IF($K604="","",IF($G604=1,(VLOOKUP($F604,'金額'!$B$3:$J$114,3,FALSE)),0))) | O604: =IF(F604="","",(L604*I604+M604+N604)) | P604: =IF($K604="","",IF($E604="KTN",(VLOOKUP($K604,'判定表'!$B$3:$I$95,8,FALSE)),IF($I604="","",(VLOOKUP($F604,'金額'!$B$3:$J$114,9,FALSE)))))
...

Sheet 2.入力表
L2: 支払総計 | M2: =N7 -> 0
C6: 日程 | D6: 曜日 | E6: 現場 | G6: 案件名 | J6: 詳細 | K6: 名前 | L6: 数量 | M6: 単価 | N6: 合計金額
E7: 合計 | F7: 合計 | J7: 合計 | L7: =SUBTOTAL(9, L8:L5771) -> 0 | N7: =SUBTOTAL(9, N8:N2725) -> 0
B8: =IF($K8="","",(VLOOKUP($K8,'判定表'!$B$3:$G$108,6,FALSE))) | D8: =IF(C8="","",upper(TEXT(C8, "DDD"))) | E8: =IF(G8="","",VLOOKUP($G8,'金額'!$N$3:$O$62,2,FALSE)) | F8: =IF(G8="","",VLOOKUP($G8,'金額'!$N$3:$Q$62,4,FALSE)) | M8: =IF(G8="","", IF(G8="Palette TIP",#REF!,VLOOKUP(G8, '金額'!$N$3:$P$62, 3, FALSE))) | N8: =IF(G8="","",(L8*M8))
B9: =IF($K9="","",(VLOOKUP($K9,'判定表'!$B$3:$G$108,6,FALSE))) | D9: =IF(C9="","",upper(TEXT(C9, "DDD"))) | E9: =IF(G9="","",VLOOKUP($G9,'金額'!$N$3:$O$62,2,FALSE)) | F9: =IF(G9="","",VLOOKUP($G9,'金額'!$N$3:$Q$62,4,FALSE)) | M9: =IF(G9="","", IF(G9="Palette TIP",#REF!,VLOOKUP(G9, '金額'!$N$3:$P$62, 3, FALSE))) | N9: =IF(G9="","",(L9*M9))
B10: =IF($K10="","",(VLOOKUP($K10,'判定表'!$B$3:$G$108,6,FALSE))) | D10: =IF(C10="","",upper(TEXT(C10, "DDD"))) | E10: =IF(G10="","",VLOOKUP($G10,'金額'!$N$3:$O$62,2,FALSE)) | F10: =IF(G10="","",VLOOKUP($G10,'金額'!$N$3:$Q$62,4,FALSE)) | M10: =IF(G10="","", IF(G10="Palette TIP",#REF!,VLOOKUP(G10, '金額'!$N$3:$P$62, 3, FALSE))) | N10: =IF(G10="","",(L10*M10))
B11: =IF($K11="","",(VLOOKUP($K11,'判定表'!$B$3:$G$108,6,FALSE))) | D11: =IF(C11="","",upper(TEXT(C11, "DDD"))) | E11: =IF(G11="","",VLOOKUP($G11,'金額'!$N$3:$O$62,2,FALSE)) | F11: =IF(G11="","",VLOOKUP($G11,'金額'!$N$3:$Q$62,4,FALSE)) | M11: =IF(G11="","", IF(G11="Palette TIP",#REF!,VLOOKUP(G11, '金額'!$N$3:$P$62, 3, FALSE))) | N11: =IF(G11="","",(L11*M11))
B12: =IF($K12="","",(VLOOKUP($K12,'判定表'!$B$3:$G$108,6,FALSE))) | D12: =IF(C12="","",upper(TEXT(C12, "DDD"))) | E12: =IF(G12="","",VLOOKUP($G12,'金額'!$N$3:$O$62,2,FALSE)) | F12: =IF(G12="","",VLOOKUP($G12,'金額'!$N$3:$Q$62,4,FALSE)) | M12: =IF(G12="","", IF(G12="Palette TIP",#REF!,VLOOKUP(G12, '金額'!$N$3:$P$62, 3, FALSE))) | N12: =IF(G12="","",(L12*M12))
B13: =IF($K13="","",(VLOOKUP($K13,'判定表'!$B$3:$G$108,6,FALSE))) | D13: =IF(C13="","",upper(TEXT(C13, "DDD"))) | E13: =IF(G13="","",VLOOKUP($G13,'金額'!$N$3:$O$62,2,FALSE)) | F13: =IF(G13="","",VLOOKUP($G13,'金額'!$N$3:$Q$62,4,FALSE)) | M13: =IF(G13="","", IF(G13="Palette TIP",#REF!,VLOOKUP(G13, '金額'!$N$3:$P$62, 3, FALSE))) | N13: =IF(G13="","",(L13*M13))
B14: =IF($K14="","",(VLOOKUP($K14,'判定表'!$B$3:$G$108,6,FALSE))) | D14: =IF(C14="","",upper(TEXT(C14, "DDD"))) | E14: =IF(G14="","",VLOOKUP($G14,'金額'!$N$3:$O$62,2,FALSE)) | F14: =IF(G14="","",VLOOKUP($G14,'金額'!$N$3:$Q$62,4,FALSE)) | M14: =IF(G14="","", IF(G14="Palette TIP",#REF!,VLOOKUP(G14, '金額'!$N$3:$P$62, 3, FALSE))) | N14: =IF(G14="","",(L14*M14))
B15: =IF($K15="","",(VLOOKUP($K15,'判定表'!$B$3:$G$108,6,FALSE))) | D15: =IF(C15="","",upper(TEXT(C15, "DDD"))) | E15: =IF(G15="","",VLOOKUP($G15,'金額'!$N$3:$O$62,2,FALSE)) | F15: =IF(G15="","",VLOOKUP($G15,'金額'!$N$3:$Q$62,4,FALSE)) | M15: =IF(G15="","", IF(G15="Palette TIP",#REF!,VLOOKUP(G15, '金額'!$N$3:$P$62, 3, FALSE))) | N15: =IF(G15="","",(L15*M15))
B16: =IF($K16="","",(VLOOKUP($K16,'判定表'!$B$3:$G$108,6,FALSE))) | D16: =IF(C16="","",upper(TEXT(C16, "DDD"))) | E16: =IF(G16="","",VLOOKUP($G16,'金額'!$N$3:$O$62,2,FALSE)) | F16: =IF(G16="","",VLOOKUP($G16,'金額'!$N$3:$Q$62,4,FALSE)) | M16: =IF(G16="","", IF(G16="Palette TIP",#REF!,VLOOKUP(G16, '金額'!$N$3:$P$62, 3, FALSE))) | N16: =IF(G16="","",(L16*M16))
B17: =IF($K17="","",(VLOOKUP($K17,'判定表'!$B$3:$G$108,6,FALSE))) | D17: =IF(C17="","",upper(TEXT(C17, "DDD"))) | E17: =IF(G17="","",VLOOKUP($G17,'金額'!$N$3:$O$62,2,FALSE)) | F17: =IF(G17="","",VLOOKUP($G17,'金額'!$N$3:$Q$62,4,FALSE)) | M17: =IF(G17="","", IF(G17="Palette TIP",#REF!,VLOOKUP(G17, '金額'!$N$3:$P$62, 3, FALSE))) | N17: =IF(G17="","",(L17*M17))
B18: =IF($K18="","",(VLOOKUP($K18,'判定表'!$B$3:$G$108,6,FALSE))) | D18: =IF(C18="","",upper(TEXT(C18, "DDD"))) | E18: =IF(G18="","",VLOOKUP($G18,'金額'!$N$3:$O$62,2,FALSE)) | F18: =IF(G18="","",VLOOKUP($G18,'金額'!$N$3:$Q$62,4,FALSE)) | M18: =IF(G18="","", IF(G18="Palette TIP",#REF!,VLOOKUP(G18, '金額'!$N$3:$P$62, 3, FALSE))) | N18: =IF(G18="","",(L18*M18))
B19: =IF($K19="","",(VLOOKUP($K19,'判定表'!$B$3:$G$108,6,FALSE))) | D19: =IF(C19="","",upper(TEXT(C19, "DDD"))) | E19: =IF(G19="","",VLOOKUP($G19,'金額'!$N$3:$O$62,2,FALSE)) | F19: =IF(G19="","",VLOOKUP($G19,'金額'!$N$3:$Q$62,4,FALSE)) | M19: =IF(G19="","", IF(G19="Palette TIP",#REF!,VLOOKUP(G19, '金額'!$N$3:$P$62, 3, FALSE))) | N19: =IF(G19="","",(L19*M19))
... B460: =IF($K460="","",(VLOOKUP($K460,'判定表'!$B$3:$G$108,6,FALSE))) | D460: =IF(C460="","",upper(TEXT(C460, "DDD"))) | E460: =IF(G460="","",VLOOKUP($G460,'金額'!$N$3:$O$62,2,FALSE)) | F460: =IF(G460="","",VLOOKUP($G460,'金額'!$N$3:$Q$62,4,FALSE)) | M460: =IF(G460="","", IF(G460="Palette TIP",#REF!,VLOOKUP(G460, '金額'!$N$3:$P$62, 3, FALSE))) | N460: =IF(G460="","",(L460*M460))
B461: =IF($K461="","",(VLOOKUP($K461,'判定表'!$B$3:$G$108,6,FALSE))) | D461: =IF(C461="","",upper(TEXT(C461, "DDD"))) | E461: =IF(G461="","",VLOOKUP($G461,'金額'!$N$3:$O$62,2,FALSE)) | F461: =IF(G461="","",VLOOKUP($G461,'金額'!$N$3:$Q$62,4,FALSE)) | M461: =IF(G461="","", IF(G461="Palette TIP",#REF!,VLOOKUP(G461, '金額'!$N$3:$P$62, 3, FALSE))) | N461: =IF(G461="","",(L461*M461)) | O461: WチェックOK
B462: =IF($K462="","",(VLOOKUP($K462,'判定表'!$B$3:$G$108,6,FALSE))) | D462: =IF(C462="","",upper(TEXT(C462, "DDD"))) | E462: =IF(G462="","",VLOOKUP($G462,'金額'!$N$3:$O$62,2,FALSE)) | F462: =IF(G462="","",VLOOKUP($G462,'金額'!$N$3:$Q$62,4,FALSE)) | M462: =IF(G462="","", IF(G462="Palette TIP",#REF!,VLOOKUP(G462, '金額'!$N$3:$P$62, 3, FALSE))) | N462: =IF(G462="","",(L462*M462))
B463: =IF($K463="","",(VLOOKUP($K463,'判定表'!$B$3:$G$108,6,FALSE))) | D463: =IF(C463="","",upper(TEXT(C463, "DDD"))) | E463: =IF(G463="","",VLOOKUP($G463,'金額'!$N$3:$O$62,2,FALSE)) | F463: =IF(G463="","",VLOOKUP($G463,'金額'!$N$3:$Q$62,4,FALSE)) | M463: =IF(G463="","", IF(G463="Palette TIP",#REF!,VLOOKUP(G463, '金額'!$N$3:$P$62, 3, FALSE))) | N463: =IF(G463="","",(L463*M463))
B464: =IF($K464="","",(VLOOKUP($K464,'判定表'!$B$3:$G$108,6,FALSE))) | D464: =IF(C464="","",upper(TEXT(C464, "DDD"))) | E464: =IF(G464="","",VLOOKUP($G464,'金額'!$N$3:$O$62,2,FALSE)) | F464: =IF(G464="","",VLOOKUP($G464,'金額'!$N$3:$Q$62,4,FALSE)) | M464: =IF(G464="","", IF(G464="Palette TIP",#REF!,VLOOKUP(G464, '金額'!$N$3:$P$62, 3, FALSE))) | N464: =IF(G464="","",(L464*M464))
B465: =IF($K465="","",(VLOOKUP($K465,'判定表'!$B$3:$G$108,6,FALSE))) | D465: =IF(C465="","",upper(TEXT(C465, "DDD"))) | E465: =IF(G465="","",VLOOKUP($G465,'金額'!$N$3:$O$62,2,FALSE)) | F465: =IF(G465="","",VLOOKUP($G465,'金額'!$N$3:$Q$62,4,FALSE)) | M465: =IF(G465="","", IF(G465="Palette TIP",#REF!,VLOOKUP(G465, '金額'!$N$3:$P$62, 3, FALSE))) | N465: =IF(G465="","",(L465*M465))
B466: =IF($K466="","",(VLOOKUP($K466,'判定表'!$B$3:$G$108,6,FALSE))) | D466: =IF(C466="","",upper(TEXT(C466, "DDD"))) | E466: =IF(G466="","",VLOOKUP($G466,'金額'!$N$3:$O$62,2,FALSE)) | F466: =IF(G466="","",VLOOKUP($G466,'金額'!$N$3:$Q$62,4,FALSE)) | M466: =IF(G466="","", IF(G466="Palette TIP",#REF!,VLOOKUP(G466, '金額'!$N$3:$P$62, 3, FALSE))) | N466: =IF(G466="","",(L466*M466))
B467: =IF($K467="","",(VLOOKUP($K467,'判定表'!$B$3:$G$108,6,FALSE))) | D467: =IF(C467="","",upper(TEXT(C467, "DDD"))) | E467: =IF(G467="","",VLOOKUP($G467,'金額'!$N$3:$O$62,2,FALSE)) | F467: =IF(G467="","",VLOOKUP($G467,'金額'!$N$3:$Q$62,4,FALSE)) | M467: =IF(G467="","", IF(G467="Palette TIP",#REF!,VLOOKUP(G467, '金額'!$N$3:$P$62, 3, FALSE))) | N467: =IF(G467="","",(L467*M467))
B468: =IF($K468="","",(VLOOKUP($K468,'判定表'!$B$3:$G$108,6,FALSE))) | D468: =IF(C468="","",upper(TEXT(C468, "DDD"))) | E468: =IF(G468="","",VLOOKUP($G468,'金額'!$N$3:$O$62,2,FALSE)) | F468: =IF(G468="","",VLOOKUP($G468,'金額'!$N$3:$Q$62,4,FALSE)) | M468: =IF(G468="","", IF(G468="Palette TIP",#REF!,VLOOKUP(G468, '金額'!$N$3:$P$62, 3, FALSE))) | N468: =IF(G468="","",(L468*M468))
B469: =IF($K469="","",(VLOOKUP($K469,'判定表'!$B$3:$G$108,6,FALSE))) | D469: =IF(C469="","",upper(TEXT(C469, "DDD"))) | E469: =IF(G469="","",VLOOKUP($G469,'金額'!$N$3:$O$62,2,FALSE)) | F469: =IF(G469="","",VLOOKUP($G469,'金額'!$N$3:$Q$62,4,FALSE)) | M469: =IF(G469="","", IF(G469="Palette TIP",#REF!,VLOOKUP(G469, '金額'!$N$3:$P$62, 3, FALSE))) | N469: =IF(G469="","",(L469*M469))
B470: =IF($K470="","",(VLOOKUP($K470,'判定表'!$B$3:$G$108,6,FALSE))) | D470: =IF(C470="","",upper(TEXT(C470, "DDD"))) | E470: =IF(G470="","",VLOOKUP($G470,'金額'!$N$3:$O$62,2,FALSE)) | F470: =IF(G470="","",VLOOKUP($G470,'金額'!$N$3:$Q$62,4,FALSE)) | M470: =IF(G470="","", IF(G470="Palette TIP",#REF!,VLOOKUP(G470, '金額'!$N$3:$P$62, 3, FALSE))) | N470: =IF(G470="","",(L470*M470))
B471: =IF($K471="","",(VLOOKUP($K471,'判定表'!$B$3:$G$108,6,FALSE))) | D471: =IF(C471="","",upper(TEXT(C471, "DDD"))) | E471: =IF(G471="","",VLOOKUP($G471,'金額'!$N$3:$O$62,2,FALSE)) | F471: =IF(G471="","",VLOOKUP($G471,'金額'!$N$3:$Q$62,4,FALSE)) | M471: =IF(G471="","", IF(G471="Palette TIP",#REF!,VLOOKUP(G471, '金額'!$N$3:$P$62, 3, FALSE))) | N471: =IF(G471="","",(L471*M471))
B472: =IF($K472="","",(VLOOKUP($K472,'判定表'!$B$3:$G$108,6,FALSE))) | D472: =IF(C472="","",upper(TEXT(C472, "DDD"))) | E472: =IF(G472="","",VLOOKUP($G472,'金額'!$N$3:$O$62,2,FALSE)) | F472: =IF(G472="","",VLOOKUP($G472,'金額'!$N$3:$Q$62,4,FALSE)) | M472: =IF(G472="","", IF(G472="Palette TIP",#REF!,VLOOKUP(G472, '金額'!$N$3:$P$62, 3, FALSE))) | N472: =IF(G472="","",(L472*M472))
B473: =IF($K473="","",(VLOOKUP($K473,'判定表'!$B$3:$G$108,6,FALSE))) | D473: =IF(C473="","",upper(TEXT(C473, "DDD"))) | E473: =IF(G473="","",VLOOKUP($G473,'金額'!$N$3:$O$62,2,FALSE)) | F473: =IF(G473="","",VLOOKUP($G473,'金額'!$N$3:$Q$62,4,FALSE)) | M473: =IF(G473="","", IF(G473="Palette TIP",#REF!,VLOOKUP(G473, '金額'!$N$3:$P$62, 3, FALSE))) | N473: =IF(G473="","",(L473*M473))
... B1696: =IF($K1696="","",(VLOOKUP($K1696,'判定表'!$B$3:$G$108,6,FALSE))) | D1696: =IF(C1696="","",upper(TEXT(C1696, "DDD"))) | E1696: =IF(G1696="","",VLOOKUP($G1696,'金額'!$N$3:$O$62,2,FALSE)) | F1696: =IF(G1696="","",VLOOKUP($G1696,'金額'!$N$3:$Q$62,4,FALSE)) | M1696: =IF(G1696="","", IF(G1696="Palette TIP",#REF!,VLOOKUP(G1696, '金額'!$N$3:$P$62, 3, FALSE))) | N1696: =IF(G1696="","",(L1696*M1696))
B1697: =IF($K1697="","",(VLOOKUP($K1697,'判定表'!$B$3:$G$108,6,FALSE))) | D1697: =IF(C1697="","",upper(TEXT(C1697, "DDD"))) | E1697: =IF(G1697="","",VLOOKUP($G1697,'金額'!$N$3:$O$62,2,FALSE)) | M1697: =IF(G1697="","", IF(G1697="Palette TIP",#REF!,VLOOKUP(G1697, '金額'!$N$3:$P$62, 3, FALSE))) | N1697: =IF(G1697="","",(L1697*M1697))
B1698: =IF($K1698="","",(VLOOKUP($K1698,'判定表'!$B$3:$G$108,6,FALSE))) | D1698: =IF(C1698="","",upper(TEXT(C1698, "DDD"))) | E1698: =IF(G1698="","",VLOOKUP($G1698,'金額'!$N$3:$O$62,2,FALSE)) | M1698: =IF(G1698="","", IF(G1698="Palette TIP",#REF!,VLOOKUP(G1698, '金額'!$N$3:$P$62, 3, FALSE))) | N1698: =IF(G1698="","",(L1698*M1698))
B1699: =IF($K1699="","",(VLOOKUP($K1699,'判定表'!$B$3:$G$108,6,FALSE))) | D1699: =IF(C1699="","",upper(TEXT(C1699, "DDD"))) | E1699: =IF(G1699="","",VLOOKUP($G1699,'金額'!$N$3:$O$62,2,FALSE)) | M1699: =IF(G1699="","", IF(G1699="Palette TIP",#REF!,VLOOKUP(G1699, '金額'!$N$3:$P$62, 3, FALSE))) | N1699: =IF(G1699="","",(L1699*M1699))
B1700: =IF($K1700="","",(VLOOKUP($K1700,'判定表'!$B$3:$G$108,6,FALSE))) | D1700: =IF(C1700="","",upper(TEXT(C1700, "DDD"))) | E1700: =IF(G1700="","",VLOOKUP($G1700,'金額'!$N$3:$O$62,2,FALSE)) | M1700: =IF(G1700="","", IF(G1700="Palette TIP",#REF!,VLOOKUP(G1700, '金額'!$N$3:$P$62, 3, FALSE))) | N1700: =IF(G1700="","",(L1700*M1700))
B1701: =IF($K1701="","",(VLOOKUP($K1701,'判定表'!$B$3:$G$108,6,FALSE))) | D1701: =IF(C1701="","",upper(TEXT(C1701, "DDD"))) | E1701: =IF(G1701="","",VLOOKUP($G1701,'金額'!$N$3:$O$62,2,FALSE)) | M1701: =IF(G1701="","", IF(G1701="Palette TIP",#REF!,VLOOKUP(G1701, '金額'!$N$3:$P$62, 3, FALSE))) | N1701: =IF(G1701="","",(L1701*M1701))
B1702: =IF($K1702="","",(VLOOKUP($K1702,'判定表'!$B$3:$G$108,6,FALSE))) | D1702: =IF(C1702="","",upper(TEXT(C1702, "DDD"))) | E1702: =IF(G1702="","",VLOOKUP($G1702,'金額'!$N$3:$O$62,2,FALSE)) | M1702: =IF(G1702="","", IF(G1702="Palette TIP",#REF!,VLOOKUP(G1702, '金額'!$N$3:$P$62, 3, FALSE))) | N1702: =IF(G1702="","",(L1702*M1702))
B1703: =IF($K1703="","",(VLOOKUP($K1703,'判定表'!$B$3:$G$108,6,FALSE))) | D1703: =IF(C1703="","",upper(TEXT(C1703, "DDD"))) | E1703: =IF(G1703="","",VLOOKUP($G1703,'金額'!$N$3:$O$62,2,FALSE)) | M1703: =IF(G1703="","", IF(G1703="Palette TIP",#REF!,VLOOKUP(G1703, '金額'!$N$3:$P$62, 3, FALSE))) | N1703: =IF(G1703="","",(L1703*M1703))
B1704: =IF($K1704="","",(VLOOKUP($K1704,'判定表'!$B$3:$G$108,6,FALSE))) | D1704: =IF(C1704="","",upper(TEXT(C1704, "DDD"))) | E1704: =IF(G1704="","",VLOOKUP($G1704,'金額'!$N$3:$O$62,2,FALSE)) | M1704: =IF(G1704="","", IF(G1704="Palette TIP",#REF!,VLOOKUP(G1704, '金額'!$N$3:$P$62, 3, FALSE))) | N1704: =IF(G1704="","",(L1704*M1704))
B1705: =IF($K1705="","",(VLOOKUP($K1705,'判定表'!$B$3:$G$108,6,FALSE))) | D1705: =IF(C1705="","",upper(TEXT(C1705, "DDD"))) | E1705: =IF(G1705="","",VLOOKUP($G1705,'金額'!$N$3:$O$62,2,FALSE)) | M1705: =IF(G1705="","", IF(G1705="Palette TIP",#REF!,VLOOKUP(G1705, '金額'!$N$3:$P$62, 3, FALSE))) | N1705: =IF(G1705="","",(L1705*M1705))
B1706: =IF($K1706="","",(VLOOKUP($K1706,'判定表'!$B$3:$G$108,6,FALSE))) | D1706: =IF(C1706="","",upper(TEXT(C1706, "DDD"))) | E1706: =IF(G1706="","",VLOOKUP($G1706,'金額'!$N$3:$O$62,2,FALSE)) | M1706: =IF(G1706="","", IF(G1706="Palette TIP",#REF!,VLOOKUP(G1706, '金額'!$N$3:$P$62, 3, FALSE))) | N1706: =IF(G1706="","",(L1706*M1706))
...

Sheet 外注連絡票
A1: ≪令和8年3月分 外注費支払表≫ | E1: 作成日： | F1: 46117
E2: 締 日 ： | F2: 46112
A3: 大阪ダンサー | E3: 支払日 ： | F3: 46139
B5: 在籍 | C5: ｺｰﾄﾞ | D5: 芸名 | E5: 氏名 | F5: 案件報酬 出演費 | G5: 案件報酬 インセンティブ | H5: 交通費 | I5: 課税支払 | J5: 所得税 （課税支払 ×10.21%） | K5: 差引支払額 | L5: 立替 | M5: 振込金額 | N5: 振込先口座 | O5: 口座番号 | P5: 口座名義 | Q5: 住所 | T5: 連絡先
B6: THP Dancers | C6: 303 | D6: 斉藤愛乃 | E6: 斎藤愛乃 | F6: =IF(E6="","", SUMIF('1.入力表'!$K$8:$K$1368,D6,'1.入力表'!$O$8:$O$1368)) -> 0 | G6: =IF(E6="","", SUMIF('2.入力表'!$K$8:$K$1650,D6,'2.入力表'!$N$8:$N$1650)) -> 0 | H6: =IF(E6="","", SUMIF('1.入力表'!$K$8:$K$1368,D6,'1.入力表'!$P$8:$P$1368)) -> 0 | I6: =IF(E6="","",SUM(F6:H6)) -> 0 | J6: =IF(E6="","",IF(I6>1000000,ROUNDDOWN(1000000*10.21%,0)+(I6-1000000)*20.42%,ROUNDDOWN(I6*10.21%,0))) -> 0 | K6: =IF(I6="","",I6-J6) -> 0 | L6: 0 | M6: =IF(E6="","",SUM(K6:L6)) -> 0 | N6: みずほ銀行 船場支店 | O6: 2048365 | P6: ｻｲﾄｳ ｱｲﾉ | Q6: 〒 | R6: 610-1113 | S6: 京都市西京区大枝南福西町2-5-8 | T6: 090-1599-1402
B7: THP Dancers | C7: - | D7: 伊藤悠亜 | E7: 金澤千夏 | F7: =IF(E7="","", SUMIF('1.入力表'!$K$8:$K$1368,D7,'1.入力表'!$O$8:$O$1368)) -> 0 | G7: =IF(E7="","", SUMIF('2.入力表'!$K$8:$K$1650,D7,'2.入力表'!$N$8:$N$1650)) -> 0 | H7: =IF(E7="","", SUMIF('1.入力表'!$K$8:$K$1368,D7,'1.入力表'!$P$8:$P$1368)) -> 0 | I7: =IF(E7="","",SUM(F7:H7)) -> 0 | J7: =IF(E7="","",IF(I7>1000000,ROUNDDOWN(1000000*10.21%,0)+(I7-1000000)*20.42%,ROUNDDOWN(I7*10.21%,0))) -> 0 | K7: =IF(I7="","",I7-J7) -> 0 | L7: 0 | M7: =IF(E7="","",SUM(K7:L7)) -> 0 | N7: 三井住友銀行 難波支店 | O7: 8322416 | P7: ｶﾅｻﾞﾜ ﾁﾅﾂ | Q7: 〒 | R7: 550-0027 | S7: 大阪府大阪市西区九条3丁目27-8九条ソリティア402 | T7: 090-2288-4870
B8: THP Dancers | C8: - | D8: 佐藤ほの | E8: 菅原帆夏 | F8: =IF(E8="","", SUMIF('1.入力表'!$K$8:$K$1372,D8,'1.入力表'!$O$8:$O$1372)) -> 0 | G8: =IF(E8="","", SUMIF('2.入力表'!$K$8:$K$1650,D8,'2.入力表'!$N$8:$N$1650)) -> 0 | H8: =IF(E8="","", SUMIF('1.入力表'!$K$8:$K$1372,D8,'1.入力表'!$P$8:$P$1372)) -> 0 | I8: =IF(E8="","",SUM(F8:H8)) -> 0 | J8: =IF(E8="","",IF(I8>1000000,ROUNDDOWN(1000000*10.21%,0)+(I8-1000000)*20.42%,ROUNDDOWN(I8*10.21%,0))) -> 0 | K8: =IF(I8="","",I8-J8) -> 0 | L8: 0 | M8: =IF(E8="","",SUM(K8:L8)) -> 0 | N8: ゆうちょ銀行 九〇八 | O8: 5120515 | P8: ｽｶﾞﾜﾗ ﾎﾉｶ | Q8: 〒 | R8: 532-0025 | S8: 大阪府大阪市淀川区新北野1丁目9-9メロディア新北野505 | T8: 080-9878-2269
B9: THP Dancers | C9: - | D9: 星野もも | E9: 深井桃香 | F9: =IF(E9="","", SUMIF('1.入力表'!$K$8:$K$1372,D9,'1.入力表'!$O$8:$O$1372)) -> 0 | G9: =IF(E9="","", SUMIF('2.入力表'!$K$8:$K$1650,D9,'2.入力表'!$N$8:$N$1650)) -> 0 | H9: =IF(E9="","", SUMIF('1.入力表'!$K$8:$K$1372,D9,'1.入力表'!$P$8:$P$1372)) -> 0 | I9: =IF(E9="","",SUM(F9:H9)) -> 0 | J9: =IF(E9="","",IF(I9>1000000,ROUNDDOWN(1000000*10.21%,0)+(I9-1000000)*20.42%,ROUNDDOWN(I9*10.21%,0))) -> 0 | K9: =IF(I9="","",I9-J9) -> 0 | L9: 0 | M9: =IF(E9="","",SUM(K9:L9)) -> 0 | N9: 京都銀行 伏見支店 | O9: 3938202 | P9: ﾌｶｲ ﾓﾓｶ | Q9: 〒 | R9: 542-0081 | S9: 大阪府大阪市中央区南船場1丁目4-12ドエル南船場801 | T9: 080-9127-2030
B10: THP Dancers | C10: 1047 | D10: 大島花織 | E10: 岡田花織 | F10: =IF(E10="","", SUMIF('1.入力表'!$K$8:$K$1372,D10,'1.入力表'!$O$8:$O$1372)) -> 0 | G10: =IF(E10="","", SUMIF('2.入力表'!$K$8:$K$1650,D10,'2.入力表'!$N$8:$N$1650)) -> 0 | H10: =IF(E10="","", SUMIF('1.入力表'!$K$8:$K$1372,D10,'1.入力表'!$P$8:$P$1372)) -> 0 | I10: =IF(E10="","",SUM(F10:H10)) -> 0 | J10: =IF(E10="","",IF(I10>1000000,ROUNDDOWN(1000000*10.21%,0)+(I10-1000000)*20.42%,ROUNDDOWN(I10*10.21%,0))) -> 0 | K10: =IF(I10="","",I10-J10) -> 0 | L10: 0 | M10: =IF(E10="","",SUM(K10:L10)) -> 0 | N10: みずほ銀行 阪急梅田支店 | O10: 3028981 | P10: ｵｶﾀﾞ ｶｵﾘ | Q10: 〒 | R10: 542-0012 | S10: 大阪府大阪市中央区谷町7-2-7 REIOS谷町802 | T10: 070-2230-2950
B11: THP Dancers | C11: 1057 | D11: 中条舞結 | E11: 中村真悠 | F11: =IF(E11="","", SUMIF('1.入力表'!$K$8:$K$1368,D11,'1.入力表'!$O$8:$O$1368)) -> 0 | G11: =IF(E11="","", SUMIF('2.入力表'!$K$8:$K$1650,D11,'2.入力表'!$N$8:$N$1650)) -> 0 | H11: =IF(E11="","", SUMIF('1.入力表'!$K$8:$K$1368,D11,'1.入力表'!$P$8:$P$1368)) -> 0 | I11: =IF(E11="","",SUM(F11:H11)) -> 0 | J11: =IF(E11="","",IF(I11>1000000,ROUNDDOWN(1000000*10.21%,0)+(I11-1000000)*20.42%,ROUNDDOWN(I11*10.21%,0))) -> 0 | K11: =IF(I11="","",I11-J11) -> 0 | L11: 0 | M11: =IF(E11="","",SUM(K11:L11)) -> 0 | N11: みずほ銀行 姫路支店 | O11: 3018632 | P11: ﾅｶﾑﾗ ﾏﾕ | Q11: 〒 | R11: 542-0081 | S11: 大阪市中央区南船場1-12-5-302 | T11: 080-2526-6248
B12: THP Dancers | C12: - | D12: 七瀬亜美 | E12: 高橋七々夏 | F12: =IF(E12="","", SUMIF('1.入力表'!$K$8:$K$1368,D12,'1.入力表'!$O$8:$O$1368)) -> 0 | G12: =IF(E12="","", SUMIF('2.入力表'!$K$8:$K$1650,D12,'2.入力表'!$N$8:$N$1650)) -> 0 | H12: =IF(E12="","", SUMIF('1.入力表'!$K$8:$K$1368,D12,'1.入力表'!$P$8:$P$1368)) -> 0 | I12: =IF(E12="","",SUM(F12:H12)) -> 0 | J12: =IF(E12="","",IF(I12>1000000,ROUNDDOWN(1000000*10.21%,0)+(I12-1000000)*20.42%,ROUNDDOWN(I12*10.21%,0))) -> 0 | K12: =IF(I12="","",I12-J12) -> 0 | L12: 0 | M12: =IF(E12="","",SUM(K12:L12)) -> 0 | N12: 三井住友銀行 府中支店 | O12: 7909982 | P12: ﾀｶﾊｼ ﾅﾅｶ | Q12: 〒 | R12: 615-0023 | S12: 京都府京都市右京区西院西平町8-2CASA西院不動ハイツ203 | T12: 090-1264-6662
B13: THP Dancers | C13: 1099 | D13: セリカ | E13: 間所玲衣 | F13: =IF(E13="","", SUMIF('1.入力表'!$K$8:$K$1368,D13,'1.入力表'!$O$8:$O$1368)) -> 0 | G13: =IF(E13="","", SUMIF('2.入力表'!$K$8:$K$1650,D13,'2.入力表'!$N$8:$N$1650)) -> 0 | H13: =IF(E13="","", SUMIF('1.入力表'!$K$8:$K$1368,D13,'1.入力表'!$P$8:$P$1368)) -> 0 | I13: =IF(E13="","",SUM(F13:H13)) -> 0 | J13: =IF(E13="","",IF(I13>1000000,ROUNDDOWN(1000000*10.21%,0)+(I13-1000000)*20.42%,ROUNDDOWN(I13*10.21%,0))) -> 0 | K13: =IF(I13="","",I13-J13) -> 0 | L13: 0 | M13: =IF(E13="","",SUM(K13:L13)) -> 0 | N13: 三井住友銀行 京阪京橋支店 | O13: 2196906 | P13: ﾏﾄﾞｺﾛ ﾚｲ | Q13: 〒 | R13: 541-0058 | S13: 大阪市中央区南久宝寺町1-5-9アーデンタワー本町イースト506 | T13: 090-6325-1696
B14: THP Dancers | C14: 1105 | D14: アスミ | E14: 大下亜純 | F14: =IF(E14="","", SUMIF('1.入力表'!$K$8:$K$1368,D14,'1.入力表'!$O$8:$O$1368)) -> 0 | G14: =IF(E14="","", SUMIF('2.入力表'!$K$8:$K$1650,D14,'2.入力表'!$N$8:$N$1650)) -> 0 | H14: =IF(E14="","", SUMIF('1.入力表'!$K$8:$K$1368,D14,'1.入力表'!$P$8:$P$1368)) -> 0 | I14: =IF(E14="","",SUM(F14:H14)) -> 0 | J14: =IF(E14="","",IF(I14>1000000,ROUNDDOWN(1000000*10.21%,0)+(I14-1000000)*20.42%,ROUNDDOWN(I14*10.21%,0))) -> 0 | K14: =IF(I14="","",I14-J14) -> 0 | L14: 0 | M14: =IF(E14="","",SUM(K14:L14)) -> 0 | N14: 三菱UFJ銀行 明石支店 | O14: 0443762 | P14: ｵｵｼﾀ ｱｽﾐ | Q14: 〒 | R14: 556-0003 | S14: 大阪府大阪市浪速区恵美須西3-14-23-402 | T14: 080-4230-1737
A15: 住所変更 | B15: THP Dancers | C15: - | D15: 西井リナ | E15: 岸部里奈 | F15: =IF(E15="","", SUMIF('1.入力表'!$K$8:$K$1368,D15,'1.入力表'!$O$8:$O$1368)) -> 0 | G15: =IF(E15="","", SUMIF('2.入力表'!$K$8:$K$1650,D15,'2.入力表'!$N$8:$N$1650)) -> 0 | H15: =IF(E15="","", SUMIF('1.入力表'!$K$8:$K$1368,D15,'1.入力表'!$P$8:$P$1368)) -> 0 | I15: =IF(E15="","",SUM(F15:H15)) -> 0 | J15: =IF(E15="","",IF(I15>1000000,ROUNDDOWN(1000000*10.21%,0)+(I15-1000000)*20.42%,ROUNDDOWN(I15*10.21%,0))) -> 0 | K15: =IF(I15="","",I15-J15) -> 0 | L15: 0 | M15: =IF(E15="","",SUM(K15:L15)) -> 0 | N15: みずほ銀行 西宮北口支店 | O15: 3011507 | P15: ｷｼﾍﾞ ﾘﾅ | Q15: 〒 | R15: 556-0006 | S15: 日本橋東1丁目12番17-701号 | T15: 080-8329-2993
B16: THP Dancers | C16: - | D16: 松尾奈美 | E16: 寺澤菜々子 | F16: =IF(E16="","", SUMIF('1.入力表'!$K$8:$K$1368,D16,'1.入力表'!$O$8:$O$1368)) -> 0 | G16: =IF(E16="","", SUMIF('2.入力表'!$K$8:$K$1650,D16,'2.入力表'!$N$8:$N$1650)) -> 0 | H16: =IF(E16="","", SUMIF('1.入力表'!$K$8:$K$1368,D16,'1.入力表'!$P$8:$P$1368)) -> 0 | I16: =IF(E16="","",SUM(F16:H16)) -> 0 | J16: =IF(E16="","",IF(I16>1000000,ROUNDDOWN(1000000*10.21%,0)+(I16-1000000)*20.42%,ROUNDDOWN(I16*10.21%,0))) -> 0 | K16: =IF(I16="","",I16-J16) -> 0 | L16: 0 | M16: =IF(E16="","",SUM(K16:L16)) -> 0 | N16: 紀陽銀行 鳳支店 | O16: 0742338 | P16: ﾃﾗｻﾜ ﾅﾅｺ | Q16: 〒 | R16: 550-0011 | S16: 大阪府大阪市西区阿波座1丁目14-6アーデンタワー西本町 401 | T16: 080-6149-9071
B17: THP Dancers | C17: - | D17: 河谷美奈 | E17: 十時実那 | F17: =IF(E17="","", SUMIF('1.入力表'!$K$8:$K$1368,D17,'1.入力表'!$O$8:$O$1368)) -> 0 | G17: =IF(E17="","", SUMIF('2.入力表'!$K$8:$K$1650,D17,'2.入力表'!$N$8:$N$1650)) -> 0 | H17: =IF(E17="","", SUMIF('1.入力表'!$K$8:$K$1368,D17,'1.入力表'!$P$8:$P$1368)) -> 0 | I17: =IF(E17="","",SUM(F17:H17)) -> 0 | J17: =IF(E17="","",IF(I17>1000000,ROUNDDOWN(1000000*10.21%,0)+(I17-1000000)*20.42%,ROUNDDOWN(I17*10.21%,0))) -> 0 | K17: =IF(I17="","",I17-J17) -> 0 | L17: 0 | M17: =IF(E17="","",SUM(K17:L17)) -> 0 | N17: りそな銀行 久米田支店 | O17: 0299706 | P17: ﾄﾄｷ ﾐﾅ | Q17: 〒 | R17: 596-0805 | S17: 岸和田市田治米町173-14 | T17: 080-9747-4963
B18: THP Dancers | C18: - | D18: 椿菜月 | E18: 新谷菜月 | F18: =IF(E18="","", SUMIF('1.入力表'!$K$8:$K$1368,D18,'1.入力表'!$O$8:$O$1368)) -> 0 | G18: =IF(E18="","", SUMIF('2.入力表'!$K$8:$K$1650,D18,'2.入力表'!$N$8:$N$1650)) -> 0 | H18: =IF(E18="","", SUMIF('1.入力表'!$K$8:$K$1368,D18,'1.入力表'!$P$8:$P$1368)) -> 0 | I18: =IF(E18="","",SUM(F18:H18)) -> 0 | J18: =IF(E18="","",IF(I18>1000000,ROUNDDOWN(1000000*10.21%,0)+(I18-1000000)*20.42%,ROUNDDOWN(I18*10.21%,0))) -> 0 | K18: =IF(I18="","",I18-J18) -> 0 | L18: 0 | M18: =IF(E18="","",SUM(K18:L18)) -> 0 | N18: 三井住友銀行 大阪西支店 | O18: 7094983 | P18: ｼﾝﾀﾆ ﾅﾂｷ | Q18: 〒 | R18: 651-0087 | S18: 兵庫県神戸市中央区御幸通３丁目1-24 エルトスト神戸302 | T18: 090-6276-2594
B19: THP Dancers | C19: - | D19: 木戸つかさ | E19: 村上つかさ | F19: =IF(E19="","", SUMIF('1.入力表'!$K$8:$K$1368,D19,'1.入力表'!$O$8:$O$1368)) -> 0 | G19: =IF(E19="","", SUMIF('2.入力表'!$K$8:$K$1650,D19,'2.入力表'!$N$8:$N$1650)) -> 0 | H19: =IF(E19="","", SUMIF('1.入力表'!$K$8:$K$1368,D19,'1.入力表'!$P$8:$P$1368)) -> 0 | I19: =IF(E19="","",SUM(F19:H19)) -> 0 | J19: =IF(E19="","",IF(I19>1000000,ROUNDDOWN(1000000*10.21%,0)+(I19-1000000)*20.42%,ROUNDDOWN(I19*10.21%,0))) -> 0 | K19: =IF(I19="","",I19-J19) -> 0 | L19: 0 | M19: =IF(E19="","",SUM(K19:L19)) -> 0 | N19: 三菱UFJ銀行 谷町支店 | O19: 0178526 | P19: ﾑﾗｶﾐ ﾂｶｻ | Q19: 〒 | R19: 540-0026 | S19: 大阪府大阪市中央区内本町1-3-6 | T19: 090-3464-7449
